Workbook

Sheet PRESENTACIÓN DE RESULTADOS
A1: Tratamiendo | B1: Enero | C1: Febrero | D1: Marzo | E1: Abril | F1: Mayo | G1: Junio | H1: Julio | I1: Agosto | J1: Septiembre | K1: Octubre | L1: Noviembre | M1: Diciembre | N1: Total
A2: Producto | B2: =SUM(Producto!H3:H19) -> 11814 | C2: =SUM(Producto!H20:H44) -> 15270 | D2: =SUM(Producto!H45:H74) -> 15426.55 | E2: =SUM(Producto!H75:H83) -> 7210 | F2: =SUM(Producto!H84:H107) -> 15220 | G2: =SUM(Producto!H108:H119) -> 7370 | H2: =SUM(Producto!H120:H138) -> 12210 | I2: =SUM(Producto!H139:H149) -> 8800 | J2: =SUM(Producto!H150:H169) -> 14040.46 | K2: =SUM(Producto!H170:H177) -> 6460 | L2: =SUM(Producto!H178:H212) -> 25000 | M2: =SUM(Producto!H213:H231) -> 13494 | N2: =SUM(B2:M2) -> 152315.01 | O2: =+Producto!H232 -> 152315.01 | P2: =+O2-N2 -> 0
A3: Acido hialuronico | B3: 0 | C3: 0 | D3: 0 | E3: 0 | F3: =SUM('Acido hialuronico'!H3) -> 2700 | G3: 0 | H3: 0 | I3: =SUM('Acido hialuronico'!H4:H5) -> 6300 | J3: 0 | K3: =SUM('Acido hialuronico'!H6) -> 2800 | L3: =SUM('Acido hialuronico'!H7:H23) -> 42000 | M3: =SUM('Acido hialuronico'!H24:H25) -> 5800 | N3: =SUM(B3:M3) -> 59600 | O3: =+'Acido hialuronico'!H26 -> 59600 | P3: =+O3-N3 -> 0
A4: Depilación | B4: =SUM(Depilación!H3:H16) -> 6212.5 | C4: =SUM(Depilación!H17:H24) -> 3950 | D4: =SUM(Depilación!H25:H36) -> 5605.25 | E4: =SUM(Depilación!H37:H39) -> 2412.5 | F4: =SUM(Depilación!H40:H48) -> 2311.25 | G4: =SUM(Depilación!H49:H65) -> 8116.5 | H4: =SUM(Depilación!H66:H83) -> 12928.75 | I4: =SUM(Depilación!H84:H93) -> 4006.25 | J4: =SUM(Depilación!H98:H109) -> 5604 | K4: =SUM(Depilación!H110:H125) -> 13721.25 | L4: =SUM(Depilación!H126:H134) -> 5861.25 | M4: =SUM(Depilación!H135:H143) -> 3854 | N4: =SUM(B4:M4) -> 74583.5 | O4: =+Depilación!H144 -> 74583.5 | P4: =+O4-N4 -> 0
A5: Emsculpt | B5: =SUM(Emsculpt!H3) -> 9000 | C5: =SUM(Emsculpt!H4) -> 6750 | D5: =SUM(Emsculpt!H5) -> 6750 | E5: =SUM(Emsculpt!H6:H7) -> 6750 | F5: =SUM(Emsculpt!H8:H9) -> 13500 | G5: 0 | H5: 0 | I5: =SUM(Emsculpt!H10) -> 6750 | J5: =SUM(Emsculpt!H11:H14) -> 20250 | K5: =SUM(Emsculpt!H15) -> 6750 | L5: =SUM(Emsculpt!H16:H20) -> 17750 | M5: =SUM(Emsculpt!H21:H27) -> 25000 | N5: =SUM(B5:M5) -> 119250 | O5: =+Emsculpt!H28 -> 119250 | P5: =+O5-N5 -> 0
A6: Emtone | B6: =SUM(Emtone!H3:H7) -> 18200 | C6: =SUM(Emtone!H8) -> 5000 | D6: =SUM(Emtone!H9:H13) -> 25100 | E6: =SUM(Emtone!H14) -> 5000 | F6: =SUM(Emtone!H15) -> 6500 | G6: =SUM(Emtone!H16:H20) -> 20000 | H6: =SUM(Emtone!H21:H22) -> 10000 | I6: =SUM(Emtone!H23) -> 5000 | J6: =SUM(Emtone!H24:H26) -> 16000 | K6: 0 | L6: =SUM(Emtone!H27:H32) -> 25590.4 | M6: =SUM(Emtone!H33:H35) -> 10000 | N6: =SUM(B6:M6) -> 146390.4 | O6: =+Emtone!H36 -> 146390.4 | P6: =+O6-N6 -> 0
A7: Exilis | B7: =SUM(Exilis!H3:H8) -> 30750 | C7: =SUM(Exilis!H9:H17) -> 32875 | D7: =SUM(Exilis!H18:H25) -> 42250 | E7: =SUM(Exilis!H26:H33) -> 42375 | F7: =SUM(Exilis!H34:H42) -> 58500 | G7: =SUM(Exilis!H43:H53) -> 45175 | H7: =SUM(Exilis!H54:H61) -> 24721 | I7: =SUM(Exilis!H62:H66) -> 18900 | J7: =SUM(Exilis!H67:H74) -> 48500 | K7: =SUM(Exilis!H75:H76) -> 7500 | L7: =SUM(Exilis!H77:H85) -> 44240 | M7: =SUM(Exilis!H86:H91) -> 22746 | N7: =SUM(B7:M7) -> 418532 | O7: =+Exilis!H92 -> 418532 | P7: =+O7-N7 -> 0
A8: Exfoliación | B8: 0 | C8: 0 | D8: 0 | E8: 0 | F8: 0 | G8: 0 | H8: 0 | I8: 0 | J8: 0 | K8: 0 | L8: 0 | M8: 0 | N8: =SUM(B8:M8) -> 0 | O8: =+Exfoliación!H4 -> 0 | P8: =+O8-N8 -> 0
A9: Facial purificante | B9: =SUM('Facial purificante'!H3:H9) -> 6057.5 | C9: =SUM('Facial purificante'!H10:H12) -> 1600 | D9: =SUM('Facial purificante'!H13:H18) -> 3200 | E9: =SUM('Facial purificante'!H19:H21) -> 2625 | F9: =SUM('Facial purificante'!H22:H35) -> 9850 | G9: =SUM('Facial purificante'!H36:H42) -> 3850 | H9: =SUM('Facial purificante'!H43:H44) -> 1782.5 | I9: =SUM('Facial purificante'!H45:H47) -> 2750 | J9: =SUM('Facial purificante'!H48:H56) -> 6900 | K9: =SUM('Facial purificante'!H57:H62) -> 3450 | L9: =SUM('Facial purificante'!H63:H72) -> 5922.5 | M9: =SUM('Facial purificante'!H73:H77) -> 5666.9999 | N9: =SUM(B9:M9) -> 53654.5 | O9: =+'Facial purificante'!H78 -> 53654.5 | P9: =+O9-N9 -> 0
A10: Hifu | B10: 0 | C10: =SUM(Hifu!H3:H5) -> 10930 | D10: 0 | E10: 0 | F10: =SUM(Hifu!H6) -> 3500 | G10: 0 | H10: =SUM(Hifu!H7:H10) -> 15200 | I10: =SUM(Hifu!H11:H12) -> 6583 | J10: 0 | K10: 0 | L10: =SUM(Hifu!H13) -> 2800 | M10: =SUM(Hifu!H14:H16) -> 13168 | N10: =SUM(B10:M10) -> 52181 | O10: =+Hifu!H17 -> 52181 | P10: =+O10-N10 -> 0
A11: Hydrafacial | B11: =SUM(Hydrafacial!H3:H4) -> 1167.6 | C11: =SUM(Hydrafacial!H5:H6) -> 3169 | D11: =SUM(Hydrafacial!H7:H8) -> 1668 | E11: 0 | F11: =SUM(Hydrafacial!H9:H10) -> 1595 | G11: =SUM(Hydrafacial!H11:H12) -> 3636.24 | H11: =SUM(Hydrafacial!H13:H17) -> 5985.4 | I11: =SUM(Hydrafacial!H18:H19) -> 2501.4 | J11: =SUM(Hydrafacial!H20:H21) -> 2502 | K11: =SUM(Hydrafacial!H22:H26) -> 6122 | L11: =SUM(Hydrafacial!H27:H29) -> 3669.6 | M11: =SUM(Hydrafacial!H30:H35) -> 6672 | N11: =SUM(B11:M11) -> 38688.24 | O11: =+Hydrafacial!H36 -> 38688.24 | P11: =+O11-N11 -> 0
A12: Laboratorios | B12: =SUM(Laboratorios!H3:H5) -> 2810 | C12: =SUM(Laboratorios!H6) -> 47 | D12: =SUM(Laboratorios!H7) -> 750 | E12: =SUM(Laboratorios!H8) -> 750 | F12: 0 | G12: 0 | H12: =SUM(Laboratorios!H9:H11) -> 2796.95 | I12: =SUM(Laboratorios!H12:H16) -> 5186.46 | J12: 0 | K12: =SUM(Laboratorios!H17) -> 750 | L12: 0 | M12: 0 | N12: =SUM(B12:M12) -> 13090.41 | O12: =+Laboratorios!H18 -> 13090.41 | P12: =+O12-N12 -> 0
A13: Masaje linfatico | B13: =SUM('Masaje linfatico'!H3:H9) -> 6097 | C13: =SUM('Masaje linfatico'!H10:H12) -> 777 | D13: =SUM('Masaje linfatico'!H13:H19) -> 6636 | E13: =SUM('Masaje linfatico'!H20:H21) -> 2950 | F13: =SUM('Masaje linfatico'!H22:H28) -> 6518 | G13: =SUM('Masaje linfatico'!H29:H32) -> 5859 | H13: =SUM('Masaje linfatico'!H33:H36) -> 5659 | I13: =SUM('Masaje linfatico'!H37:H42) -> 6577 | J13: =SUM('Masaje linfatico'!H43:H47) -> 5459 | K13: =SUM('Masaje linfatico'!H48:H50) -> 3459 | L13: =SUM('Masaje linfatico'!H51:H54) -> 6059 | M13: =SUM('Masaje linfatico'!H55:H57) -> 4700 | N13: =SUM(B13:M13) -> 60750 | O13: =+'Masaje linfatico'!H58 -> 60750 | P13: =+O13-N13 -> 0
A14: Mesoterapia | B14: =SUM(Mesoterapia!H3) -> 4800 | C14: =SUM(Mesoterapia!H4) -> 2400 | D14: =SUM(Mesoterapia!H5:H9) -> 9490 | E14: =SUM(Mesoterapia!H10:H12) -> 9900 | F14: =SUM(Mesoterapia!H13) -> 3400 | G14: 0 | H14: =SUM(Mesoterapia!H14:H15) -> 4420 | I14: =SUM(Mesoterapia!H16) -> 5000 | J14: =SUM(Mesoterapia!H17:H20) -> 16100 | K14: 0 | L14: =SUM(Mesoterapia!H21:H22) -> 7397.6 | M14: =SUM(Mesoterapia!H23) -> 2500 | N14: =SUM(B14:M14) -> 65407.6 | O14: =+Mesoterapia!H24 -> 65407.6 | P14: =+O14-N14 -> 0
A15: Morpheus | B15: =SUM(Morpheus!H3:H18) -> 101200 | C15: =SUM(Morpheus!H19:H23) -> 50000 | D15: =SUM(Morpheus!H24:H41) -> 210000 | E15: =SUM(Morpheus!H42:H52) -> 125000 | F15: =SUM(Morpheus!H53:H66) -> 156500 | G15: =SUM(Morpheus!H67:H76) -> 85000 | H15: =SUM(Morpheus!H77:H82) -> 70000 | I15: =SUM(Morpheus!H83:H97) -> 145000 | J15: =SUM(Morpheus!H98:H101) -> 40000 | K15: =SUM(Morpheus!H102:H108) -> 80000 | L15: =SUM(Morpheus!H109:H115) -> 70000 | M15: =SUM(Morpheus!H116:H120) -> 50000 | N15: =SUM(B15:M15) -> 1182700 | O15: =+Morpheus!H121 -> 1182700 | P15: =+O15-N15 -> 0
A16: Pico-láser | B16: 0 | C16: =SUM('Pico-láser'!H3:H5) -> 5300 | D16: 0 | E16: 0 | F16: 0 | G16: 0 | H16: 0 | I16: 0 | J16: 0 | K16: 0 | L16: 0 | M16: 0 | N16: =SUM(B16:M16) -> 5300 | O16: =+'Pico-láser'!H6 -> 5300 | P16: =+O16-N16 -> 0
A17: Powershape | B17: =SUM(Powershape!H3) -> 1596 | C17: 0 | D17: 0 | E17: 0 | F17: 0 | G17: 0 | H17: 0 | I17: 0 | J17: 0 | K17: 0 | L17: 0 | M17: 0 | N17: =SUM(B17:M17) -> 1596 | O17: =+Powershape!H4 -> 1596 | P17: =+O17-N17 -> 0
A18: Profhilo | B18: 0 | C18: 0 | D18: 0 | E18: 0 | F18: 0 | G18: 0 | H18: =SUM(Profhilo!H3) -> 3000 | I18: 0 | J18: 0 | L18: =SUM(Profhilo!H4:H5) -> 10000 | M18: =SUM(Profhilo!H6:H11) -> 13750 | N18: =SUM(B18:M18) -> 26750 | O18: =+Profhilo!H12 -> 26750 | P18: =+O18-N18 -> 0
A19: PRP | B19: =SUM(PRP!H3:H5) -> 7040 | C19: =SUM(PRP!H6:H22) -> 34970 | D19: =SUM(PRP!H23:H27) -> 11200 | E19: =SUM(PRP!H28:H36) -> 8020 | F19: =SUM(PRP!H37:H59) -> 44442 | G19: =SUM(PRP!H60:H74) -> 30978.4 | H19: =SUM(PRP!H75:H92) -> 52400 | I19: =SUM(PRP!H93:H103) -> 30900 | J19: =SUM(PRP!H104:H144) -> 60200 | K19: =SUM(PRP!H145:H154) -> 21020 | L19: =SUM(PRP!H155:H161) -> 15400 | M19: =SUM(PRP!H162:H170) -> 23360 | N19: =SUM(B19:M19) -> 339930.4 | O19: =+PRP!H171 -> 339930.4 | P19: =+O19-N19 -> 0
A20: Radiofrecuencia | B20: =SUM(Radiofrecuencia!H3:H8) -> 16680 | C20: =SUM(Radiofrecuencia!H9) -> 1670 | D20: =SUM(Radiofrecuencia!H10:H13) -> 10560 | E20: =SUM(Radiofrecuencia!H14) -> 1780 | F20: =SUM(Radiofrecuencia!H15) -> 3560 | G20: =SUM(Radiofrecuencia!H16:H24) -> 24640 | H20: =SUM(Radiofrecuencia!H25:H33) -> 24676 | I20: =SUM(Radiofrecuencia!H34:H38) -> 7200 | J20: =SUM(Radiofrecuencia!H39:H46) -> 21002 | K20: =SUM(Radiofrecuencia!H47:H48) -> 8880 | L20: =SUM(Radiofrecuencia!H49:H51) -> 12015 | M20: =SUM(Radiofrecuencia!H52:H59) -> 21350 | N20: =SUM(B20:M20) -> 154013 | O20: =+Radiofrecuencia!H60 -> 154013 | P20: =+O20-N20 -> 0
A21: Ultrasonido | B21: 0 | C21: =SUM(Ultrasonido!H3) -> 220 | D21: =SUM(Ultrasonido!H4:H5) -> 1230 | E21: =SUM(Ultrasonido!H6:H11) -> 4020 | F21: =SUM(Ultrasonido!H12:H17) -> 5680 | G21: =SUM(Ultrasonido!H18:H23) -> 9450 | H21: =SUM(Ultrasonido!H24:H26) -> 3780 | I21: =SUM(Ultrasonido!H27:H28) -> 2880 | J21: =SUM(Ultrasonido!H29:H34) -> 6590 | K21: =SUM(Ultrasonido!H35) -> 180 | L21: =SUM(Ultrasonido!H36) -> 360 | M21: =SUM(Ultrasonido!H37) -> 1620 | N21: =SUM(B21:M21) -> 36010 | O21: =+Ultrasonido!H38 -> 36010 | P21: =+O21-N21 -> 0
A22: Velo de acido hialuronico | B22: =SUM('Velo de acido hialuronico'!H3:H6) -> 2550 | C22: =SUM('Velo de acido hialuronico'!H7) -> 650 | D22: 0 | E22: 0 | F22: 0 | G22: 0 | H22: 0 | I22: 0 | J22: =SUM('Velo de acido hialuronico'!H8:H11) -> 5960 | K22: 0 | L22: =SUM('Velo de acido hialuronico'!H12) -> 650 | M22: 0 | N22: =SUM(B22:M22) -> 9810 | O22: =+'Velo de acido hialuronico'!H13 -> 9810 | P22: =+O22-N22 -> 0
A23: Velox | B23: =SUM(Velox!H3) -> 2856 | C23: 0 | D23: =SUM(Velox!H4) -> 2128 | E23: =SUM(Velox!H5) -> 2500 | F23: =SUM(Velox!H6) -> 2240 | G23: =SUM(Velox!H7:H8) -> 6256 | H23: =SUM(Velox!H9:H10) -> 6528 | I23: =SUM(Velox!H11:H13) -> 6280 | J23: 0 | K23: =SUM(Velox!H14:H15) -> 5320 | L23: =SUM(Velox!H16:H17) -> 1700 | M23: =SUM(Velox!H18) -> 4000 | N23: =SUM(B23:M23) -> 39808 | O23: =+Velox!H19 -> 39808 | P23: =+O23-N23 -> 0
A24: Verju | B24: =SUM(Verju!H3:H5) -> 10100 | C24: =SUM(Verju!H6) -> 708.33 | D24: 0 | E24: 0 | F24: 0 | G24: 0 | H24: 0 | I24: 0 | J24: 0 | K24: 0 | L24: 0 | M24: 0 | N24: =SUM(B24:M24) -> 10808.33 | O24: =+Verju!H7 -> 10808.33 | P24: =+O24-N24 -> 0
A25: Vitamina C intravenosa | B25: =SUM('Vitamina C intravenosa'!H3:H26) -> 16969.5 | C25: =SUM('Vitamina C intravenosa'!H27:H47) -> 18503 | D25: =SUM('Vitamina C intravenosa'!H48:H60) -> 15940 | E25: =SUM('Vitamina C intravenosa'!H61:H71) -> 8560 | F25: =SUM('Vitamina C intravenosa'!H72:H87) -> 19795 | G25: =SUM('Vitamina C intravenosa'!H88:H101) -> 17412.6 | H25: =SUM('Vitamina C intravenosa'!H102:H109) -> 10700 | I25: =SUM('Vitamina C intravenosa'!H110:H120) -> 7998 | J25: =SUM('Vitamina C intravenosa'!H121:H141) -> 24451 | K25: =SUM('Vitamina C intravenosa'!H142:H156) -> 18026 | L25: =SUM('Vitamina C intravenosa'!H157:H174) -> 23916 | M25: =SUM('Vitamina C intravenosa'!H175:H183) -> 13751 | N25: =SUM(B25:M25) -> 196022.1 | O25: =+'Vitamina C intravenosa'!H184 -> 196022.1 | P25: =+O25-N25 -> 0
A26: Ciclo coolsculpting | B26: 0 | C26: 0 | D26: 0 | E26: =SUM('Ciclo coolsculpting'!H3) -> 18000 | F26: 0 | G26: 0 | H26: 0 | I26: =SUM('Ciclo coolsculpting'!H4) -> 9000 | J26: 0 | K26: 0 | L26: 0 | M26: 0 | N26: =SUM(B26:M26) -> 27000 | O26: =+'Ciclo coolsculpting'!H5 -> 27000 | P26: =+O26-N26 -> 0
A27: Cliovana | B27: 0 | C27: 0 | D27: 0 | E27: 0 | F27: 0 | G27: 0 | H27: 0 | I27: 0 | J27: 0 | K27: 0 | L27: 0 | M27: 0 | N27: =SUM(B27:M27) -> 0 | O27: =+Cliovana!H4 -> 0 | P27: =+O27-N27 -> 0
A28: Dermapen | B28: =SUM(Dermapen!H3) -> 3000 | C28: =SUM(Dermapen!H4:H8) -> 8160 | D28: 0 | E28: =SUM(Dermapen!H9) -> 3300 | F28: =SUM(Dermapen!H10:H11) -> 4300 | G28: =SUM(Dermapen!H12:H15) -> 4900 | H28: =SUM(Dermapen!H16) -> 1000 | I28: 0 | J28: 0 | K28: =SUM(Dermapen!H17) -> 1280 | L28: =SUM(Dermapen!H18) -> 3300 | M28: =SUM(Dermapen!H19) -> 3240 | N28: =SUM(B28:M28) -> 32480 | O28: =+Dermapen!H20 -> 32480 | P28: =+O28-N28 -> 0
A29: Láser CO2 | B29: =SUM('Láser CO2'!H3) -> 3900 | C29: 0 | D29: =SUM('Láser CO2'!H4) -> 5000 | E29: 0 | F29: =SUM('Láser CO2'!H5:H6) -> 10680 | G29: 0 | H29: 0 | I29: 0 | J29: 0 | K29: 0 | L29: =SUM('Láser CO2'!H7:H8) -> 9500 | M29: 0 | N29: =SUM(B29:M29) -> 29080 | O29: =+'Láser CO2'!H9 -> 29080 | P29: =+O29-N29 -> 0
A30: Masaje relajante | B30: =SUM('Masaje relajante'!H3:H4) -> 550 | C30: =SUM('Masaje relajante'!H5) -> 280 | D30: 0 | E30: 0 | F30: =SUM('Masaje relajante'!H6) -> 2000 | G30: =SUM('Masaje relajante'!H7:H8) -> 1050 | H30: =SUM('Masaje relajante'!H9) -> 250 | I30: =SUM('Masaje relajante'!H10) -> 250 | J30: =SUM('Masaje relajante'!H11:H12) -> 2400 | K30: 0 | L30: 0 | M30: =SUM('Masaje relajante'!H13:H14) -> 3250 | N30: =SUM(B30:M30) -> 10030 | O30: =+'Masaje relajante'!H15 -> 10030 | P30: =+O30-N30 -> 0
A31: Oligoelementos | B31: 0 | C31: 0 | D31: 0 | E31: 0 | F31: 0 | G31: 0 | H31: 0 | I31: 0 | J31: 0 | K31: 0 | L31: 0 | M31: 0 | N31: =SUM(B31:M31) -> 0 | O31: =+Oligoelementos!H4 -> 0 | P31: =+O31-N31 -> 0
A32: Grow | B32: =SUM(Grow!H3:H8) -> 20202.09 | C32: =SUM(Grow!H9:H14) -> 20002.09 | D32: =SUM(Grow!H15:H19) -> 19552.09 | E32: =SUM(Grow!H20:H24) -> 19552.09 | F32: =SUM(Grow!H25:H30) -> 19752.09 | G32: =SUM(Grow!H31:H35) -> 19552.09 | H32: =SUM(Grow!H36:H40) -> 13732.09 | I32: =SUM(Grow!H41:H44) -> 8662.09 | J32: =SUM(Grow!H45:H47) -> 7572.59 | K32: 0 | L32: =SUM(Grow!H48:H53) -> 15824.18 | M32: =SUM(Grow!H54:H57) -> 9662.09 | N32: =SUM(B32:M32) -> 174065.58 | O32: =+Grow!H58 -> 174065.58 | P32: =+O32-N32 -> 0
A33: Abonos | B33: 0 | C33: 0 | D33: =SUM('Abonos a tratamientos'!H3) -> 95 | E33: 0 | F33: 0 | G33: 0 | H33: 0 | I33: 0 | J33: 0 | K33: 0 | L33: 0 | M33: 0 | N33: =SUM(B33:M33) -> 95 | O33: =+'Abonos a tratamientos'!H4 -> 95 | P33: =+O33-N33 -> 0
A34: Celulas madre | B34: =SUM('Celulas madre'!H3:H4) -> 50600 | C34: 0 | D34: =SUM('Celulas madre'!H5) -> 22750 | E34: =SUM('Celulas madre'!H6) -> 24250 | F34: 0 | G34: 0 | H34: =SUM('Celulas madre'!H7:H8) -> 45400 | I34: =SUM('Celulas madre'!H9) -> 19150 | J34: 0 | K34: =SUM('Celulas madre'!H10:H11) -> 52350 | L34: 0 | M34: 0 | N34: =SUM(B34:M34) -> 214500 | O34: =+'Celulas madre'!H12 -> 214500 | P34: =+O34-N34 -> 0
A35: Lipo-recover | B35: 0 | C35: 0 | D35: 0 | E35: 0 | F35: 0 | G35: 0 | H35: 0 | I35: 0 | J35: 0 | K35: 0 | L35: 0 | M35: 0 | N35: =SUM(B35:M35) -> 0 | O35: =+'Lipo-recover'!H4 -> 0 | P35: =+O35-N35 -> 0
A36: Peeling | B36: 0 | C36: 0 | D36: 0 | E36: 0 | F36: 0 | G36: 0 | H36: 0 | I36: 0 | J36: 0 | K36: 0 | L36: 0 | M36: 0 | N36: =SUM(B36:M36) -> 0 | O36: =+Peeling!H4 -> 0 | P36: =+O36-N36 -> 0
A37: Spectra ginecologico | B37: =SUM('Spectra ginecologico'!H3:H6) -> 10000 | C37: =SUM('Spectra ginecologico'!H7:H11) -> 15810 | D37: 0 | E37: =SUM('Spectra ginecologico'!H12:H14) -> 13999.998 | F37: 0 | G37: =SUM('Spectra ginecologico'!H15:H20) -> 19105 | H37: =SUM('Spectra ginecologico'!H21) -> 6000 | I37: =SUM('Spectra ginecologico'!H22:H23) -> 2905 | J37: =SUM('Spectra ginecologico'!H24:H25) -> 4300 | K37: =SUM('Spectra ginecologico'!H26) -> 6000 | L37: =SUM('Spectra ginecologico'!H27:H31) -> 17610 | M37: 0 | N37: =SUM(B37:M37) -> 95729.998 | O37: =+'Spectra ginecologico'!H32 -> 95729.998 | P37: =+O37-N37 -> 0
A38: Vanquish | B38: 0 | C38: 0 | D38: 0 | E38: 0 | F38: 0 | G38: 0 | H38: 0 | I38: 0 | J38: 0 | K38: 0 | L38: 0 | M38: 0 | N38: =SUM(B38:M38) -> 0 | O38: =+Vanquish!H4 -> 0 | P38: =+O38-N38 -> 0
A39: Elimación de lunares | B39: 0 | C39: 0 | D39: 0 | E39: 0 | F39: 0 | G39: 0 | H39: 0 | I39: 0 | J39: 0 | K39: 0 | L39: 0 | M39: 0 | N39: =SUM(B39:M39) -> 0 | O39: =+'Eliminación de lunares'!H4:H4 -> 0 | P39: =+O39-N39 -> 0
A40: Botox | B40: 0 | C40: 0 | D40: =SUM(Botox!H3:H118) -> 242478.49 | E40: 0 | F40: 0 | G40: 0 | H40: =SUM(Botox!H119:H248) -> 285873.49 | I40: 0 | J40: 0 | K40: 0 | L40: =SUM(Botox!H249:H354) -> 236280.2 | M40: =SUM(Botox!H355:H358) -> 9240 | N40: =SUM(B40:M40) -> 773872.18 | O40: =+Botox!H359 -> 773872.18 | P40: =+O40-N40 -> 0
...

Sheet Producto
A1: Producto | B1: Fecha | C1: No. de Factura | D1: Cantidad | E1: Nombre del Paciente | F1: Tratamiento | G1: Forma de Pago | H1: Total
B3: 44936 | C3: 2717010146 | D3: 1 | E3: Patricia Sandoval | F3: Complete collagen (protocol) | G3: Efectivo | H3: 850
B4: 44937 | C4: 1511474418 | D4: 1 | E4: Mimi de Quan | F4: Frasco de protocol colageno con acido hialuronico | G4: Credomatic | H4: 550
B5: 44938 | C5: 2010334081 | D5: 1 | E5: Karla Pinto Portillo | F5: Suero regenerativo (SKINGENUITY) | G5: Efectivo $ | H5: 1010
B6: 44938 | C6: 2010334081 | D6: 1 | E6: Karla Pinto Portillo | F6: Suero reparado (SKINGENUITY) | G6: Efectivo $ | H6: 1294
B7: 44938 | C7: 174280333 | D7: 1 | E7: Norma de Barquin | F7: Protector solar spray (HELIOCARE) | G7: Efectivo | H7: 380
B8: 44938 | C8: 174280333 | D8: 1 | E8: Norma de Barquin | F8: Protector solar compacto (HELIOCARE) | G8: Efectivo | H8: 450
B9: 44943 | C9: 521751306 | D9: 1 | E9: Sara Mayorga | F9: RHA Serum | G9: Visa L. | H9: 1280
B10: 44943 | C10: recibo | D10: 1 | E10: Massiel Hernandez | F10: Protector solar spray (HELIOCARE) | G10: Efectivo | H10: 150
B11: 44943 | C11: recibo | D11: 1 | E11: Massiel Hernandez | F11: Protector solar gel (HELIOCARE) | G11: Efectivo | H11: 80
B12: 44944 | C12: 3839773296 | D12: 1 | E12: Vanessa Smith de Vargas | F12: Protector solar compacto (HELIOCARE) | G12: Credomatic | H12: 450
B13: 44951 | C13: 1237468518 | D13: 1 | E13: Zuleima Cruz Salguero | F13: RHA Serum | G13: Visa | H13: 1280
B14: 44952 | C14: 4032643175 | D14: 1 | E14: Cristina Sanchez | F14: Serun AOX C&E | G14: Visa | H14: 850
B15: 44952 | C15: recibo | D15: 2 | E15: Dra Julia Monroy | F15: Protector solar gel (HELIOCARE) | G15: Efectivo | H15: 160
B16: 44953 | C16: 2905163280 | D16: 3 | E16: Wanda Serovic | F16: Frasco de protocol colageno con acido hialuronico | G16: Credomatic | H16: 1650
B17: 44953 | C17: 2905163280 | D17: 1 | E17: Wanda Serovic | F17: Proto-col collagen Shot | G17: Credomatic | H17: 650
B18: 44953 | C18: 1582714813 | D18: 1 | E18: Wanda Serovic | F18: Protector solar spray (HELIOCARE) | G18: Credomatic | H18: 380
B19: 44956 | C19: 3581166546 | D19: 1 | E19: Silvia Patricia Oxon | F19: Protector solar gel (HELIOCARE) | G19: Credomatic | H19: 350
B20: 44960 | C20: 2773371547 | D20: 1 | E20: Alma Gricel Tobar | F20: Frasco de protocol colageno con acido hialuronico | G20: Visa | H20: 550
B21: 44960 | C21: 2773371547 | D21: 1 | E21: Alma Gricel Tobar | F21: Serum AOX C&E | G21: Visa | H21: 850
B22: 44964 | C22: 907168346 | D22: 1 | E22: Mimi de Quan | F22: Frasco de protocol colageno con acido hialuronico | G22: Credomatic | H22: 550
B23: 44964 | C23: 2333755906 | D23: 1 | E23: Mimi de Quan | F23: Serum AOX C&E | G23: Credomatic | H23: 850
B24: 44964 | C24: recibo | D24: 1 | E24: Johana Barillas | F24: Protector solar spray (HELIOCARE) | G24: Efectivo | H24: 149
B25: 44964 | C25: recibo | D25: 1 | E25: Massiel Hernandez | F25: complete collagen (protocol) | G25: Efectivo | H25: 289
B26: 44965 | C26: 2990883213 | D26: 1 | E26: Miguel Angel Martinez Solis | F26: Jabon biretix | G26: Efectivo | H26: 450
B27: 44965 | C27: 2990883213 | D27: 1 | E27: Miguel Angel Martinez Solis | F27: Abono a protector solar gel (HELIOCARE) | G27: Efectivo | H27: 140
B28: 44965 | C28: 2990883213 | D28: 1 | E28: Miguel Angel Martinez Solis | F28: Cancelación a protector solar gel (HELIOCARE) | G28: Visa | H28: 210
B29: 44965 | C29: 2990883213 | D29: 1 | E29: Miguel Angel Martinez Solis | F29: Tensage Cram (Endocare) | G29: Visa | H29: 630
B30: 44965 | C30: 1778601715 | D30: 1 | E30: Claudia Valenzuela | F30: Suero regenerativo (SKINGENUITY) | G30: Visa L. | H30: 1010
B31: 44965 | C31: 1778601715 | D31: 1 | E31: Claudia Valenzuela | F31: Suero reparador (SKINGENUITY) | G31: Visa L. | H31: 1294
B32: 44965 | C32: 1778601715 | D32: 1 | E32: Claudia Valenzuela | F32: Tensage Cram (Endocare) | G32: Visa L. | H32: 630
B33: 44965 | C33: 3225373309 | D33: 1 | E33: Diana Linares | F33: Xxtralash | G33: Credomatic | H33: 850
B34: 44967 | C34: 4090774266 | D34: 1 | E34: Anggie Gelvets | F34: Faja post-quirurgica IC 3001 | G34: Efectivo | H34: 1000
B35: 44970 | C35: 133842754 | D35: 1 | E35: Alex Weller | F35: Tensage Cram (Endocare) | G35: Visa | H35: 630
B36: 44971 | C36: 669467521 | D36: 1 | E36: Miguel Angel Martinez Solis | F36: Frasco de protocol colageno con acido hialuronico | G36: Efectivo | H36: 550
B37: 44973 | C37: recibo | D37: 1 | E37: Anderson Tay | F37: Jabon facial sinaklein (Venustras) | G37: Efectivo | H37: 38
B38: 44974 | C38: 1808812747 | D38: 1 | E38: Ileana de Carrera | F38: Protector solar compacto (HELIOCARE) | G38: Credomatic | H38: 450
B39: 44974 | C39: 1808812747 | D39: 1 | E39: Ileana de Carrera | F39: Frasco de capsulas heliocare Ultra-D | G39: Credomatic | H39: 450
B40: 44977 | C40: 3658958771 | D40: 1 | E40: Mirna Sarceño | F40: Protector solar gel (heliocare) | G40: Visa | H40: 350
B41: 44977 | C41: 64045497 | D41: 1 | E41: Abel Escartin | F41: Faja post-quirurgica para hombre codio 10596CAM (factura con exención de IVA) | G41: Visa | H41: 900
...

Sheet Acido hialuronico
A1: Acido hialuronico | B1: Fecha | C1: No. de Factura | D1: Cantidad | E1: Nombre del Paciente | F1: Tratamiento | G1: Forma de Pago | H1: Total
B3: 45076 | C3: 2420588771 | D3: 1 | E3: Mayra Mazariegos de Mendez | F3: Aplicación acido hialuronico en labios | G3: Deposito | H3: 2700
B4: 45146 | C4: 539969771 | D4: 1 | E4: Virginia Castillo | F4: Aplicación de acido hiluronico | G4: Visa | H4: 2800
B5: 45146 | C5: 539969771 | D5: 1 | E5: Virginia Castillo | F5: Aplicación de acido hiluronico | G5: Visa | H5: 3500
B6: 45223 | C6: 3094757961 | D6: 1 | E6: Mariana Orellana | F6: Aplicación acido hialuronico | G6: Deposito | H6: 2800
B7: 45244 | C7: 953174132 | D7: 1 | E7: Marilyn Barascout | F7: Aplicación acido hialuronico | G7: Credomatic | H7: 2000
B8: 45250 | C8: 882855121 | D8: 1 | E8: Ana Elizabeth Molina | F8: Aplicación acido hialuronico labios | G8: Deposito | H8: 2000
B9: 45250 | C9: 2203995018 | D9: 1 | E9: Mabby Morales | F9: Aplicación acido hialuronico nariz | G9: Visa | H9: 2800
B10: 45251 | C10: 1582253869 | D10: 1 | E10: Gabriela Valverde | F10: Aplicación acido hialuronico labios | G10: Visa | H10: 2000
B11: 45251 | C11: 3206301846 | D11: 1 | E11: Ana Marina Martinez | F11: Aplicación acido hialuronico | G11: Cheque | H11: 1000
B12: 45251 | C12: 1824017879 | D12: 1 | E12: Ana Marina Martinez | F12: Aplicación acido hialuronico | G12: Cheque | H12: 1000
B13: 45252 | C13: 3799663895 | D13: 1 | E13: Gabriela Toledo Torres | F13: Aplicación acido hialuronico labios | G13: Credomatic | H13: 2000
B14: 45252 | C14: 3799663895 | D14: 1 | E14: Gabriela Toledo Torres | F14: Aplicación acido hialuronico nariz | G14: Credomatic | H14: 2700
... B25: 45280 | C25: 2469150969 | D25: 1 | E25: Carla Sena | F25: Aplicación acido hialuronico nariz | G25: Credomatic | H25: 3000
E26: Total | H26: =SUM(H3:H25) -> 59600

Sheet Depilación
A1: Depilación | B1: Fecha | C1: No. de Factura | D1: Cantidad | E1: Nombre del Paciente | F1: Tratamiento | G1: Forma de Pago | H1: Total
B3: 44930 | C3: 2650292592 | D3: 4 | E3: Keren Noriega | F3: Depilación rostro completo | G3: Visa L. | H3: 925
B4: 44935 | C4: 2105886131 | D4: 4 | E4: Gabriela Alfaro | F4: Depilación axila | G4: Credomatic | H4: 700
B5: 44935 | C5: 2105886131 | D5: 4 | E5: Gabriela Alfaro | F5: Depilación bigote | G5: Credomatic | H5: 500
B6: 44938 | C6: 2590655824 | D6: 4 | E6: Lissete Sanchez | F6: Depilación axila | G6: Visa | H6: 700
B7: 44938 | C7: 2590655824 | D7: 4 | E7: Lissete Sanchez | F7: Depilación bikini | G7: Visa | H7: 925
B8: 44939 | C8: 322626027 | D8: 4 | E8: Claudia Arrecis | F8: Depilación bikini | G8: Efectivo | H8: 925
B9: 44939 | C9: 322626027 | D9: 4 | E9: Claudia Arrecis | F9: Depilación axila | G9: Efectivo | H9: 700
B10: 44943 | C10: recibo | D10: 1 | E10: Marleni Castillo | F10: Depilación bikini | G10: Efectivo | H10: 50
B11: 44944 | C11: 1712474995 | D11: 1 | E11: Nicte Cifuentes | F11: Depilación bikini | G11: Credomatic | H11: 231.25
B12: 44944 | C12: 2637121956 | D12: 1 | E12: Mishel de Reitzel | F12: Depilación axila | G12: Credomatic | H12: 175
B13: 44946 | C13: recibo | D13: 1 | E13: Melany Perez | F13: Depilación bikini | G13: Efectivo | H13: 50
B14: 44946 | C14: recibo | D14: 1 | E14: Melany Perez | F14: Depilación bigote | G14: Efectivo | H14: 50
B15: 44946 | C15: recibo | D15: 1 | E15: Melany Perez | F15: Depilación axila | G15: Efectivo | H15: 50
B16: 44951 | C16: 2698856826 | D16: 1 | E16: Mishel de Reitzel | F16: Depilación bikini | G16: Credomatic | H16: 231.25
B17: 44960 | C17: 2463973448 | D17: 4 | E17: Claudia Castillo | F17: Depilación rostro completo | G17: Credomatic | H17: 1200
B18: 44965 | C18: 1255358974 | D18: 4 | E18: Claudia Campos | F18: Depilación rostro completo | G18: Visa L. | H18: 925
B19: 44977 | C19: 32523008433 | D19: 4 | E19: Evelyn Cerna | F19: Depilación bikini | G19: Visa | H19: 925
B20: 44977 | C20: 32523008433 | D20: 4 | E20: Evelyn Cerna | F20: Depilación axila | G20: Visa | H20: 700
B21: 44985 | C21: recibo | D21: 1 | E21: Marleni Castillo | F21: Depilación bikini | G21: Efectivo | H21: 50
B22: 44985 | C22: recibo | D22: 1 | E22: Melany Perez | F22: Depilación bikini | G22: Efectivo | H22: 50
B23: 44985 | C23: recibo | D23: 1 | E23: Melany Perez | F23: Depilación axila | G23: Efectivo | H23: 50
B24: 44985 | C24: recibo | D24: 1 | E24: Melany Perez | F24: Depilación bigote | G24: Efectivo | H24: 50
B25: 44986 | C25: 676678220 | D25: 1 | E25: Mishel De Reitzel | F25: Depilación axila | G25: Visa | H25: 175
B26: 44986 | C26: 483411296 | D26: 2 | E26: Carla De Zelaya | F26: Depilación medias piernas | G26: Credomatic | H26: 900
B27: 44992 | C27: 935936691 | D27: 4 | E27: Anhara Silvia Chacon De Sandoval | F27: Depilación bigote, menton, antebrazo, abdomen y dedos de manos y pies | G27: Visa L. | H27: 960
B28: 44993 | C28: 3919724872 | D28: 1 | E28: Mishel De Reitzel | F28: Depilación bikini | G28: Credomatic | H28: 231.25
B29: 45000 | C29: 2113880679 | D29: 2 | E29: Norma De Barquin | F29: Depilación barbilla | G29: Credomatic | H29: 760
B30: 45007 | C30: 226118147 | D30: 4 | E30: Danury Samayoa | F30: Depilación rostro completo | G30: Visa | H30: 900
B31: 45008 | C31: 670256428 | D31: 1 | E31: Marilu Pierri | F31: Depilación bikini | G31: Credomatic | H31: 264.5
B32: 45008 | C32: 670256428 | D32: 1 | E32: Marilu Pierri | F32: Depilación axila | G32: Credomatic | H32: 264.5
B33: 45013 | C33: 806895864 | D33: 4 | E33: Bianca Conte | F33: Depilación rostro completo | G33: Visa | H33: 1000
B34: 45016 | C34: recibo | D34: 1 | E34: Melany Perez | F34: Depilación axila | G34: Efectivo | H34: 50
B35: 45016 | C35: recibo | D35: 1 | E35: Melany Perez | F35: Depilación bigote | G35: Efectivo | H35: 50
B36: 45016 | C36: recibo | D36: 1 | E36: Melany Perez | F36: Depilación bikini | G36: Efectivo | H36: 50
B37: 45033 | C37: 822560300 | D37: 4 | E37: Johana Tamyo | F37: Depilación dedos de pies | G37: Credomatic | H37: 700
B38: 45033 | C38: 822560300 | D38: 2 | E38: Johana Tamyo | F38: Depilación bikini | G38: Credomatic | H38: 462.5
B39: 45042 | C39: 1737247359 | D39: 4 | E39: Evelyn Cerna | F39: Depilación piernas | G39: Credomatic | H39: 1250
B40: 45048 | C40: 319441993 | D40: 2 | E40: Claudia Leon De Castillo | F40: Depilació bikini | G40: Visa L. | H40: 432
B41: 45048 | C41: 319441993 | D41: 1 | E41: Claudia Leon De Castillo | F41: Depilació bikini | G41: Visa L. | H41: 218
...

Sheet Emsculpt
A1: Emsculpt | B1: Fecha | C1: No. de Factura | D1: Cantidad | E1: Nombre del Paciente | F1: Tratamiento | G1: Forma de Pago | H1: Total
B3: 44931 | C3: 8077385 | D3: 4 | E3: Nicolle Melville | F3: Emsculpt abdomen | G3: Visa | H3: 9000
B4: 44974 | C4: 3501213210 | D4: 3 | E4: Maria Olga De Cohen | F4: Emsculpt abdomen | G4: Visa | H4: 6750
B5: 45001 | C5: 1605652076 | D5: 3 | E5: Maria Jose Ruano | F5: Emsculpt glúteos | G5: Visa L. | H5: 6750
B6: 45042 | C6: 148586966 | D6: 2 | E6: Natalie Recinos Sarceño | F6: Abono a emsculpt abdomen | G6: Credomatic | H6: 5958
B7: 45042 | C7: 148586966 | D7: 1 | E7: Natalie Recinos Sarceño | F7: Cancelación a emsculpt abdomen | G7: Efectivo $ | H7: 792
B8: 45051 | C8: 2861254121 | D8: 3 | E8: Alvaro Francisco Ruata | F8: Emsculpt abdomen | G8: Credomatic | H8: 6750
B9: 45062 | C9: 2313700579 | D9: 3 | E9: Maria Jose Alvarez | F9: Emsculpt gluteos | G9: Visa | H9: 6750
B10: 45148 | C10: 1342522360 | D10: 3 | E10: Jocob Cifuentes Veliz | F10: Emsculpt abdomen | G10: Visa | H10: 6750
B11: 45174 | C11: 3648736166 | D11: 3 | E11: Miguel Martinez | F11: Emsculpt abdomen | G11: Visa | H11: 6750
B12: 45194 | C12: 1860976643 | D12: 3 | E12: Jose Manuel Castellanos | F12: Emsculpt abdomen | G12: Visa L. | H12: 6750
B13: 45194 | C13: 2102086755 | D13: 2 | E13: Sara Bolaños | F13: Abono a tratamiento Emsculpt abdomen | G13: Deposito | H13: 6500
B14: 45194 | C14: 2102086755 | D14: 1 | E14: Sara Bolaños | F14: Cancelación a tratamiento Emsculpt abdomen | G14: Visa L. | H14: 250
... B27: 45279 | C27: 3414117226 | D27: 1 | E27: Maria Jose Alvarez | F27: Emsculpt glúteos | G27: Visa | H27: 1750
E28: Total | H28: =SUM(H3:H27) -> 119250

Sheet Emtone
A1: Emtone | B1: Fecha | C1: No. de Factura | D1: Cantidad | E1: Nombre del Paciente | F1: Tratamiento | G1: Forma de Pago | H1: Total
B3: 44930 | C3: 3021422995 | D3: 5 | E3: Perla Karina Alfaro Ortiz | F3: Emtone chaparrera, entrepierna, banana roll y parte posterior de la pierna | G3: Visa | H3: 4955
B4: 44930 | C4: 3021422995 | D4: 1 | E4: Perla Karina Alfaro Ortiz | F4: Emtone chaparrera, entrepierna, banana roll y parte posterior de la pierna | G4: Visa | H4: 995
B5: 44942 | C5: 363789713 | D5: 4 | E5: Nicte Alfaro | F5: Emtone abdomen, cintura y brazos | G5: Visa | H5: 2250
B6: 44944 | C6: 74597906 | D6: 8 | E6: Myriam Mijanos Ramirez | F6: Emtone medias piernans completas | G6: Visa | H6: 5000
B7: 44953 | C7: 1879916783 | D7: 8 | E7: Norma Pineda | F7: Emtone medias piernas completas | G7: Visa | H7: 5000
B8: 44977 | C8: 414729941 | D8: 8 | E8: Giselle Sanzogni | F8: Emtone medias piernas completas | G8: Credomatic | H8: 5000
B9: 44993 | C9: 3498920069 | D9: 8 | E9: Marta Maria Perez | F9: Emtone chaparrera, entrepiernas y parte posterior de la pierna | G9: Visa | H9: 5000
B10: 44995 | C10: 2773897014 | D10: 8 | E10: Nancy Paola Gudiel | F10: Emtone medias piernas completas | G10: Visa | H10: 5000
B11: 45000 | C11: 1661946787 | D11: 8 | E11: Maria Jose Herrera | F11: Emtone medias piernas y glúteos | G11: Credomatic | H11: 5100
B12: 45000 | C12: 1430015315 | D12: 8 | E12: Nicte Alfaro | F12: Emtone corporal | G12: Visa | H12: 5000
B13: 45007 | C13: 226118147 | D13: 8 | E13: Danury Samayoa | F13: Emtone chaparrera, entrepierna y parte posterior de la pierna y glúteos | G13: Visa | H13: 5000
B14: 45040 | C14: 1392791543 | D14: 8 | E14: Myriam Mijangos | F14: Emtone abdomen y cintura | G14: Visa | H14: 5000
... B35: 45279 | C35: 4218899378 | D35: 8 | E35: Edna Beatriz Suchite | F35: Emtone corporal | G35: Visa L. | H35: 5000
E36: Total | H36: =SUM(H3:H35) -> 146390.4

Sheet Exilis
A1: Exilis | B1: Fecha | C1: No. de Factura | D1: Cantidad | E1: Nombre del Paciente | F1: Tratamiento | G1: Forma de Pago | H1: Total
B3: 44930 | C3: 1419134061 | D3: 8 | E3: Rita Miranda Ovalle | F3: Exilis abdomen, cintura y espalda alta | G3: Visa | H3: 6500
B4: 44937 | C4: 2805746571 | D4: 8 | E4: Maggie Villela | F4: Exilis abdomen, cintura y espalda | G4: Visa L. | H4: 6500
B5: 44938 | C5: 2674674021 | D5: 1 | E5: Lissete Sanchez | F5: Abono a exilis piernas completas y abdomen | G5: Credomatic | H5: 5000
B6: 44942 | C6: 363789713 | D6: 8 | E6: Nicte Alfaro | F6: Exilis abdomen, cintura, espalda alta y brazos | G6: Visa | H6: 6250
B7: 44957 | C7: 379734400 | D7: 7 | E7: Dora Janeth De La Cruz De Monterroso | F7: Exilis abdomen, cintura y espalda alta | G7: Visa L. | H7: 5999.9996
B8: 44957 | C8: 379734400 | D8: 1 | E8: Dora Janeth De La Cruz De Monterroso | F8: Exilis abdomen, cintura y espalda alta | G8: Visa | H8: 500
B9: 44965 | C9: 2990883213 | D9: 1 | E9: Miguel Angel Martinez Solis | F9: Abono a exilis rostro y cuello | G9: Visa | H9: 3300
B10: 44965 | C10: 197673098 | D10: 8 | E10: Miguel Angel Martinez Solis | F10: Exilis abdomen, cintura y espalda baja | G10: Deposito | H10: 6500
B11: 44965 | C11: 197673098 | D11: 1 | E11: Miguel Angel Martinez Solis | F11: Cancelación a exilis rostro y cuello | G11: Deposito | H11: 1000
B12: 44970 | C12: 133842754 | D12: 8 | E12: Alex Weller | F12: Exilis abdomen, cintura y espalda baja | G12: Visa | H12: 6500
B13: 44970 | C13: 133842754 | D13: 6 | E13: Alex Weller | F13: Exilis rostro y cuello | G13: Visa | H13: 3900
B14: 44978 | C14: 3439806162 | D14: 8 | E14: Maria Jose Ruano | F14: Exilis abdomen, cintura y espalda | G14: Visa L. | H14: 6250
... B91: 45280 | C91: 3358608807 | D91: 1 | E91: Katherine Jordan | F91: Cancelción a exilis abdomen y cintura | G91: Visa L. | H91: 5000
E92: Total | H92: =SUM(H3:H91) -> 418532

Sheet Exfoliación
A1: Exfoliación | B1: Fecha | C1: No. de Factura | D1: Cantidad | E1: Nombre del Paciente | F1: Tratamiento | G1: Forma de Pago | H1: Total
B3: --- | C3: --- | D3: --- | E3: --- | F3: --- | G3: --- | H3: 0
E4: Total | H4: =SUM(H3:H3) -> 0

Sheet Facial purificante
A1: Facial purificante | B1: Fecha | C1: No. de Factura | D1: Cantidad | E1: Nombre del Paciente | F1: Tratamiento | G1: Forma de Pago | H1: Total
B3: 44931 | C3: 4230107039 | D3: 3 | E3: Dulce Marleny Vielman | F3: Facial purificante | G3: Visa | H3: 1725
B4: 44932 | C4: 735333448 | D4: 1 | E4: Patricia Gonzalez Starrs | F4: Facial purificante | G4: Visa | H4: 575
B5: 44935 | C5: 3232188127 | D5: 1 | E5: Diego Castillo | F5: Facial purificante | G5: Credomatic | H5: 575
B6: 44935 | C6: 3232188127 | D6: 1 | E6: Isabel Castillo | F6: Facial purificante | G6: Credomatic | H6: 402.5
B7: 44945 | C7: 2642757293 | D7: 2 | E7: Maziel Arango | F7: Facial purificante | G7: Efectivo | H7: 1150
B8: 44946 | C8: 770460610 | D8: 2 | E8: Juan Carlos Eguizabal | F8: Facial purificante | G8: Efectivo | H8: 1150
B9: 44956 | C9: 3581166546 | D9: 1 | E9: Silvia Patricia Oxon | F9: Facial purificante | G9: Credomatic | H9: 480
B10: 44959 | C10: 512640849 | D10: 1 | E10: Marjorie Manzo | F10: Facial purificante | G10: Credomatic | H10: 575
B11: 44964 | C11: 417089747 | D11: 1 | E11: Maria Renée Solares | F11: Facial purificante | G11: Credomatic | H11: 575
B12: 44972 | C12: 3909766254 | D12: 1 | E12: Ana Elizabeth Molina | F12: Facial purificante | G12: Visa | H12: 450
B13: 44986 | C13: 2863615258 | D13: 1 | E13: Ada Tejeda | F13: Facial purificante | G13: Deposito | H13: 450
B14: 44986 | C14: 792480024 | D14: 1 | E14: Ana Herbruger | F14: Facial purificante | G14: Credomatic | H14: 450
... B77: 45275 | C77: 1260866636 | D77: 2 | E77: Monica Lorena Martinez | F77: Facial purificante | G77: Visa L. | H77: 1150
E78: Total | H78: =SUM(H3:H77) -> 53654.5

Sheet Hifu
A1: Hifu | B1: Fecha | C1: No. de Factura | D1: Cantidad | E1: Nombre del Paciente | F1: Tratamiento | G1: Forma de Pago | H1: Total
B3: 44960 | C3: 814694929 | D3: 1 | E3: Alma Gricel Tobar | F3: Hifu ovalo facial y papada | G3: Deposito | H3: 4830
B4: 44972 | C4: 134558227 | D4: 1 | E4: Lydia Reyes | F4: Hifu ovalo facial y papada | G4: Visa | H4: 2600
B5: 44978 | C5: 827080822 | D5: 1 | E5: Ana Gislena Banus | F5: Hifu ovalo facial y papada | G5: Credomatic | H5: 3500
B6: 45075 | C6: 1881883923 | D6: 1 | E6: Jessie Tefel | F6: Hifu ovalo facial y papada | G6: Visa | H6: 3500
B7: 45113 | C7: 3871690244 | D7: 1 | E7: Ruth Sazo | F7: Hifu ovalo facial y papada | G7: Visa | H7: 3000
B8: 45118 | C8: 2111391586 | D8: 1 | E8: Ana Maria Teran | F8: Hifu ovalo facial y papada | G8: Visa | H8: 3000
B9: 45125 | C9: 3176480898 | D9: 1 | E9: Claudia Castillo | F9: Hifu ovalo facial y papada | G9: Visa L. | H9: 3200
B10: 45125 | C10: 1658585 | D10: 2 | E10: Esther Pacheco | F10: Hifu ovalo facial y papada | G10: Visa L. | H10: 6000
B11: 45146 | C11: 539969771 | D11: 1 | E11: Virginia Castillo | F11: Hifu ovalo facial y papada | G11: Visa | H11: 3200
B12: 45147 | C12: 366178616 | D12: 1 | E12: Maria Fernanda Remon | F12: Hifu ovalo facial y papada | G12: Visa | H12: 3383
B13: 45237 | C13: 3280356856 | D13: 1 | E13: Maria Teresa Arriola | F13: Hifu ovalo facial y papada | G13: Visa | H13: 2800
B14: 45268 | C14: 1388595424 | D14: 1 | E14: Gabriela Toledo | F14: Hifu ovalo facial y papada | G14: Credomatic | H14: 3500
... B16: 45271 | C16: 1752452591 | D16: 2 | E16: Melvin Quijivix | F16: Hifu ovalo facial y papada | G16: Deposito | H16: 4834
E17: Total | H17: =SUM(H3:H16) -> 52181

Sheet Hydrafacial
A1: Hydrafacial | B1: Fecha | C1: No. de Factura | D1: Cantidad | E1: Nombre del Paciente | F1: Tratamiento | G1: Forma de Pago | H1: Total
B3: 44932 | C3: 1691175570 | D3: 1 | E3: Lia Sanchez | F3: Hydrafacial | G3: Visa | H3: 583.8
B4: 44953 | C4: 2139636298 | D4: 1 | E4: Marisol Coronado | F4: Hydrafacial | G4: Credomatic | H4: 583.8
B5: 44972 | C5: 2819113225 | D5: 4 | E5: Wendy Marisol Gonzalez | F5: Hydrafacial | G5: Credomatic | H5: 2335
B6: 44973 | C6: 1258243715 | D6: 1 | E6: Elisa De Gil | F6: Hydrafacial | G6: Cheque | H6: 834
B7: 45000 | C7: 3855565521 | D7: 1 | E7: Johana Tamayo | F7: Hydrafacial | G7: Credomatic | H7: 834
B8: 45015 | C8: 2439464289 | D8: 1 | E8: Marcela Barquin | F8: Hydrafacial | G8: Credomatic | H8: 834
B9: 45048 | C9: 3585820799 | D9: 2 | E9: Rony Caballero | F9: Hydrafacial | G9: Efectivo | H9: 1160
B10: 45048 | C10: 3585820799 | D10: 1 | E10: Rony Caballero | F10: Hydrafacial | G10: Efectivo | H10: 435
B11: 45079 | C11: 3294710955 | D11: 1 | E11: Elisa Gil De Dedet | F11: Hydrafacial | G11: Cheque | H11: 834
B12: 45104 | C12: 988760668 | D12: 3 | E12: Andrea Rottmann | F12: Hydrafacial | G12: Credomatic | H12: 2802.24
B13: 45111 | C13: 521881109 | D13: 1 | E13: Jessica Chour | F13: Hydrafacial | G13: Visa | H13: 600
B14: 45121 | C14: 1501382008 | D14: 3 | E14: Gabriela Morales | F14: Hydrafacial | G14: Credomatic | H14: 1800
... B35: 45278 | C35: 182013905 | D35: 2 | E35: Katherine Jordan | F35: Hydrafacial | G35: Visa L. | H35: 1668
E36: Total | H36: =SUM(H3:H35) -> 38688.24

Sheet Laboratorios
A1: Laboratorios | B1: Fecha | C1: No. de Factura | D1: Cantidad | E1: Nombre del Paciente | F1: Tratamiento | G1: Forma de Pago | H1: Total
B3: 44942 | C3: 3683404304 | D3: 1 | E3: Ninive Vargas | F3: Laboratorios | G3: Credomatic | H3: 910
B4: 44946 | C4: 4259727711 | D4: 1 | E4: Victor Sagastume | F4: Laboratorios | G4: Visa | H4: 950
B5: 44946 | C5: 2951302643 | D5: 1 | E5: Sandra Fain | F5: Laboratorios | G5: Efectivo | H5: 950
B6: 44985 | C6: recibo | D6: 1 | E6: Gricel Chun | F6: Laboratorios | G6: Efectivo | H6: 47
B7: 44992 | C7: 2930526121 | D7: 1 | E7: Luis Castellanos | F7: Laboratorios | G7: Cheque | H7: 750
B8: 45043 | C8: 2201175240 | D8: 1 | E8: Evelyn Hernandez | F8: Laboratorios | G8: Visa | H8: 750
B9: 45121 | C9: 3320005399 | D9: 1 | E9: Mabby Morales | F9: Laboratorios | G9: Visa | H9: 750
B10: 45121 | C10: 3320005399 | D10: 1 | E10: Luis Leonel Morales | F10: Laboratorios | G10: Visa | H10: 850
B11: 45121 | C11: 3320005399 | D11: 1 | E11: Luis Leonel Morales | F11: Laboratorios | G11: Visa | H11: 1196.95
B12: 45139 | C12: 261639467 | D12: 1 | E12: Norma De Barquin | F12: Laboratorios | G12: Credomatic | H12: 1363.46
B13: 45142 | C13: 467091746 | D13: 1 | E13: Carlos Rodolfo De La Vega | F13: Laboratorios | G13: Efectivo | H13: 1135
B14: 45148 | C14: recibo | D14: 1 | E14: Dra Carolina Martinez | F14: Laboratorios | G14: Efectivo | H14: 788
B15: 45149 | C15: 3546759955 | D15: 1 | E15: Erica Mancilla | F15: Laboratorios | G15: Visa | H15: 850
B16: 45154 | C16: 2380808937 | D16: 1 | E16: Jacqueline Rottman | F16: Laboratorios pellets femenino | G16: Credomatic | H16: 1050
B17: 45218 | C17: 644236177 | D17: 1 | E17: Huerta Reina | F17: Laboratorios | G17: Visa | H17: 750
E18: Total | H18: =SUM(H3:H17) -> 13090.41

Sheet Masaje linfatico
A1: Masaje linfatico | B1: Fecha | C1: No. de Factura | D1: Cantidad | E1: Nombre del Paciente | F1: Tratamiento | G1: Forma de Pago | H1: Total
B3: 44935 | C3: 3402256232 | D3: 7 | E3: Sherlee Perez | F3: Masaje linfatico | G3: Visa | H3: 1400
B4: 44938 | C4: 244845665 | D4: 1 | E4: Mishel de Reitzel | F4: Masaje linfatico | G4: Credomatic | H4: 259
B5: 44943 | C5: 179322914 | D5: 8 | E5: Karla Jordan | F5: Masaje linfatico | G5: Visa | H5: 1600
B6: 44944 | C6: 2637121956 | D6: 1 | E6: Mishel de Reitzel | F6: Masaje linfatico | G6: Credomatic | H6: 259
B7: 44951 | C7: 2698856826 | D7: 1 | E7: Mishel de Reitzel | F7: Masaje linfatico | G7: Credomatic | H7: 259
B8: 44952 | C8: 4032643175 | D8: 8 | E8: Cristina Sanchez | F8: Masaje linfatico | G8: Visa | H8: 1600
B9: 44952 | C9: 1875525855 | D9: 6 | E9: Susy Villas | F9: Masaje linfatico facial | G9: Credomatic | H9: 720
B10: 44958 | C10: 1820609236 | D10: 1 | E10: Mishel De Reitzel | F10: Masaje linfatico | G10: Credomatic | H10: 259
B11: 44970 | C11: 3013034004 | D11: 1 | E11: Mishel De Reitzel | F11: Masaje linfatico | G11: Credomatic | H11: 259
B12: 44978 | C12: 2237089643 | D12: 1 | E12: Mishel De Reitzel | F12: Masaje linfatico | G12: Credomatic | H12: 259
B13: 44986 | C13: 676678220 | D13: 1 | E13: Mishel De Reitzel | F13: Masaje linfatico | G13: Visa | H13: 259
B14: 44993 | C14: 3919724872 | D14: 1 | E14: Mishel De Reitzel | F14: Masaje linfatico | G14: Credomatic | H14: 259
... B57: 45280 | C57: 3696904271 | D57: 1 | E57: Gabriela Pinto De Pontaza | F57: Masaje linfatico | G57: Credomatic | H57: 200
E58: Total | H58: =SUM(H3:H57) -> 60750

Sheet Mesoterapia
A1: Mesoterapia | B1: Fecha | C1: No. de Factura | D1: Cantidad | E1: Nombre del Paciente | F1: Tratamiento | G1: Forma de Pago | H1: Total
B3: 44942 | C3: 363789713 | D3: 10 | E3: Nicte Alfaro | F3: Mesoterapia abdomen, cintura, espalda alta y brazos | G3: Visa | H3: 4800
B4: 44963 | C4: 3139913013 | D4: 5 | E4: Rosario Palma Recinos | F4: Mesoterapia reductora abdomen y cintura | G4: Credomatic | H4: 2400
B5: 44993 | C5: 390285133 | D5: 10 | E5: Eunice Herrera Escobar | F5: Mesoterapia vitamina C glúteos | G5: Credomatic | H5: 3840
B6: 45000 | C6: 1430015315 | D6: 7 | E6: Nicte Alfaro | F6: Mesoterapia corporal | G6: Visa | H6: 3276
B7: 45000 | C7: 1430015315 | D7: 1 | E7: Nicte Alfaro | F7: Mesoterapia corporal | G7: Visa | H7: 474
B8: 45007 | C8: 226118147 | D8: 5 | E8: Danury Samayoa | F8: Mesoterapia banana roll solo lado derecho | G8: Visa | H8: 1580
B9: 45007 | C9: 226118147 | D9: 1 | E9: Danury Samayoa | F9: Mesoterapia banana roll solo lado derecho | G9: Visa | H9: 320
B10: 45034 | C10: 3294577217 | D10: 5 | E10: Sara Abularach | F10: Mesoterapia abdomen, cintura y gorditos de espalda alta | G10: Visa L. | H10: 2500
B11: 45035 | C11: 4027205059 | D11: 10 | E11: Maria Jose Garcia | F11: Mesoterapia | G11: Credomatic | H11: 4600
B12: 45040 | C12: 1392791543 | D12: 8 | E12: Myriam Mijangos | F12: Mesoterapia reductora abdomen y cintura | G12: Visa | H12: 2800
B13: 45076 | C13: 347491152 | D13: 5 | E13: Maria Elvia Navichoc | F13: Mesoterpia | G13: Cheque | H13: 3400
B14: 45111 | C14: 134762245 | D14: 5 | E14: Maria Jose Solares | F14: Mesoterapia reductora | G14: Visa L. | H14: 2210
... B23: 45268 | C23: 1388595424 | D23: 5 | E23: Gabriela Toledo | F23: Mesoterapia | G23: Credomatic | H23: 2500
E24: Total | H24: =SUM(H3:H23) -> 65407.6

Sheet Morpheus
A1: Morpheus | B1: Fecha | C1: No. de Factura | D1: Cantidad | E1: Nombre del Paciente | F1: Tratamiento | G1: Forma de Pago | H1: Total
B3: 44931 | C3: 1878802740 | D3: 3 | E3: Mabby Morales | F3: Morpheus rostro y cuello | G3: Visa L. | H3: 15000
B4: 44949 | C4: 3707128998 | D4: 1 | E4: Irene Martensen De Granados | F4: Abono a morpheus rostro y cuello | G4: Credomatic | H4: 3000
B5: 44949 | C5: 3707128998 | D5: 1 | E5: Irene Martensen De Granados | F5: Cancelación a morpheus rostro y cuello | G5: Visa | H5: 7000
B6: 44951 | C6: 3612299139 | D6: 1 | E6: Maria Cristina Martinez | F6: Morpheus rostro y cuello | G6: Visa L. | H6: 5000
B7: 44951 | C7: 2363966048 | D7: 1 | E7: Lorena de Gomez | F7: Abono a morpheus rostro y cuello | G7: Visa | H7: 6000
B8: 44951 | C8: 1261391501 | D8: 1 | E8: Lorena de Gomez | F8: Abono a morpheus rostro y cuello | G8: Visa | H8: 2000
B9: 44951 | C9: 3393276124 | D9: 1 | E9: Lorena de Gomez | F9: Abono a morpheus rostro y cuello | G9: Visa | H9: 2000
B10: 44951 | C10: 4048045569 | D10: 1 | E10: Lorena de Gomez | F10: Cancelación a morpheus rostro y cuello | G10: Visa | H10: 1200
B11: 44951 | C11: 1475561296 | D11: 2 | E11: Elizabeth Nicte Paz | F11: Morpheus rostro y cuello | G11: Visa | H11: 10000
B12: 44951 | C12: 1562135199 | D12: 2 | E12: Elizabeth Nicte Paz (mamá) | F12: Morpheus rostro y cuello | G12: Visa | H12: 10000
B13: 44953 | C13: 2905163280 | D13: 2 | E13: Wanda Serovic | F13: Morpheus rostro y cuello | G13: Credomatic | H13: 10000
B14: 44956 | C14: 680020621 | D14: 2 | E14: Karla Sarti De Bonatti | F14: Morpheus rostro y cuello | G14: Credomatic | H14: 10000
... B120: 45279 | C120: 1916421311 | D120: 2 | E120: Gabriela Pinto De Pontaza | F120: Morpheus rostro y cuello | G120: Visa | H120: 10000
E121: Total | H121: =SUM(H3:H120) -> 1182700

Sheet Pico-láser
A1: Pico-láser | B1: Fecha | C1: No. de Factura | D1: Cantidad | E1: Nombre del Paciente | F1: Tratamiento | G1: Forma de Pago | H1: Total
B3: 44974 | C3: 135104321 | D3: 2 | E3: Lisbeth Lopez | F3: Pico-láser | G3: Credomatic | H3: 1950
B4: 44978 | C4: 496257727 | D4: 3 | E4: Silvia Carolina Godoy | F4: Pico-láser | G4: Credomatic | H4: 2550
B5: 44978 | C5: 2865907652 | D5: 1 | E5: Lisbeth Estrada | F5: Pico-láser | G5: Efectivo | H5: 800
E6: Total | H6: =SUM(H3:H5) -> 5300

Sheet Powershape
A1: Powershape | B1: Fecha | C1: No. de Factura | D1: Cantidad | E1: Nombre del Paciente | F1: Tratamiento | G1: Forma de Pago | H1: Total
B3: 44930 | C3: 3021422995 | D3: 6 | E3: Perla Karina Alfaro Ortiz | F3: Powershape chaparrera, parte posterior de la pierna y moldeo de glúteos | G3: Visa | H3: 1596
E4: Total | H4: =SUM(H3:H3) -> 1596

Sheet Profhilo
A1: Porfhilo | B1: Fecha | C1: No. de Factura | D1: Cantidad | E1: Nombre del Paciente | F1: Tratamiento | G1: Forma de Pago | H1: Total
B3: 45135 | C3: 942162860 | D3: 1 | E3: Poala Monteagudo | F3: Aplicación de profhilo | G3: Credomatic | H3: 3000
B4: 45253 | C4: 2194294972 | D4: 2 | E4: Astrid Alvarado | F4: Aplicación de profhilo | G4: Credomatic | H4: 5000
B5: 45259 | C5: 1157187004 | D5: 2 | E5: Sandra Beatriz Alvarado | F5: Aplicación de profhilo | G5: Visa | H5: 5000
B6: 45266 | C6: 2525646246 | D6: 1 | E6: Karina Martinez | F6: Aplicación de profhilo | G6: Credomatic | H6: 2500
B7: 45272 | C7: 2205044553 | D7: 1 | E7: Sonia Oviedo | F7: Abono a tratamiento profhilo | G7: Visa | H7: 375
B8: 45272 | C8: 1297172486 | D8: 1 | E8: Sonia Oviedo | F8: Cancelación a tratamiento profhilo | G8: Visa | H8: 2125
B9: 45272 | C9: recibo | D9: 1 | E9: Gladys Del Cid De Escobar | F9: Aplicación de profhilo | G9: Efectivo | H9: 1250
B10: 45273 | C10: 4105324177 | D10: 1 | E10: Claudia Maria Jose Morales Donis | F10: Aplicación de profhilo | G10: Credomatic | H10: 2500
B11: 45274 | C11: 1990544598 | D11: 1 | E11: Yesenia Larrazabal | F11: Aplicación de profhilo | G11: Visa | H11: 5000
E12: Total | H12: =SUM(H3:H11) -> 26750

Sheet PRP
A1: PRP | B1: Fecha | C1: No. de Factura | D1: Cantidad | E1: Nombre del Paciente | F1: Tratamiento | G1: Forma de Pago | H1: Total
B3: 44930 | C3: 3620160573 | D3: 3 | E3: Annie Dougherty | F3: PRP rostro y cuello | G3: Visa L. | H3: 2880
B4: 44949 | C4: 828653815 | D4: 3 | E4: María Saravia | F4: PRP rostro y cuello | G4: Visa L. | H4: 3360
B5: 44952 | C5: 1869037945 | D5: 1 | E5: Gisela Castillo | F5: PRP rostro | G5: Cheque | H5: 800
B6: 44958 | C6: 2348895448 | D6: 1 | E6: Ruth Sazo | F6: PRP rostro y cuello | G6: Credomatic | H6: 1600
B7: 44958 | C7: 2348895448 | D7: 1 | E7: Ruth Sazo | F7: PRP escote | G7: Credomatic | H7: 1400
B8: 44958 | C8: 2348895448 | D8: 1 | E8: Ruth Sazo | F8: PRP rodillas | G8: Credomatic | H8: 1500
B9: 44958 | C9: 2348895448 | D9: 1 | E9: Ruth Sazo | F9: PRP manos | G9: Credomatic | H9: 1350
B10: 44958 | C10: 2348895448 | D10: 1 | E10: Ruth Sazo | F10: PRP antebrazo | G10: Credomatic | H10: 1600
B11: 44959 | C11: 484722330 | D11: 1 | E11: Vanessa Smith de Vargas | F11: PRP rostro y cuello | G11: Visa L. | H11: 1600
B12: 44965 | C12: 2990883213 | D12: 3 | E12: Miguel Angel Martinez Solis | F12: PRP rostro y cuello | G12: Visa | H12: 3360
B13: 44967 | C13: 1075922045 | D13: 3 | E13: Andrea Meany | F13: PRP Capilar | G13: Credomatic | H13: 1800
B14: 44970 | C14: 133842754 | D14: 3 | E14: Alex Weller | F14: PRP rostro y cuello | G14: Visa | H14: 3360
... B170: 45278 | C170: 1634549823 | D170: 3 | E170: Ana Maria Teran | F170: PRP rostro y cuello | G170: Visa L. | H170: 3000
E171: Total | H171: =SUM(H3:H170) -> 339930.4

Sheet Radiofrecuencia
A1: Radiofrecuencia | B1: Fecha | C1: No. de Factura | D1: Cantidad | E1: Nombre del Paciente | F1: Tratamiento | G1: Forma de Pago | H1: Total
B3: 44936 | C3: 1634550648 | D3: 1 | E3: Anneliese Wintzer | F3: Radiofrecuencia rostro y cuello | G3: Credomatic | H3: 450
B4: 44939 | C4: 322626027 | D4: 6 | E4: Claudia Arrecis | F4: Radiofrecuencia rostro y cuello | G4: Efectivo | H4: 2670
B5: 44939 | C5: 322626027 | D5: 5 | E5: Claudia Arrecis | F5: Radiofrecuencia abdomen, cintura, brazos y piernas | G5: Efectivo | H5: 6665
B6: 44939 | C6: 322626027 | D6: 1 | E6: Claudia Arrecis | F6: Radiofrecuencia abdomen, cintura, brazos y piernas | G6: Efectivo | H6: 1335
B7: 44946 | C7: 4289874178 | D7: 5 | E7: Maria Josee Solares | F7: Radiofecuencia rostro y cuello | G7: Visa L. | H7: 2000
B8: 44952 | C8: 4032643175 | D8: 8 | E8: Cristina Sanchez | F8: Radiofrecuencia rostro y cuello | G8: Visa | H8: 3560
B9: 44978 | C9: 533087440 | D9: 1 | E9: Norma Florian | F9: Cancelación a radiofrecuencia abdomen, cintura, espalda alta y gluteos | G9: Visa | H9: 1670
B10: 44992 | C10: 1207914449 | D10: 5 | E10: Raquel Calderon | F10: Radiofrecuencia abdomen, cintura y espalda | G10: Credomatic | H10: 3330
B11: 44992 | C11: 1207914449 | D11: 1 | E11: Raquel Calderon | F11: Radiofrecuencia abdomen, cintura y espalda | G11: Credomatic | H11: 670
B12: 44998 | C12: 2993833710 | D12: 6 | E12: Monica Merida De León | F12: Radiofrecuencia rostro y cuello | G12: Visa L. | H12: 3000
B13: 44999 | C13: 2015381660 | D13: 8 | E13: Dora De La Cruz | F13: Radiofrecuencia abdomen, cintura y espalda alta | G13: Visa L. | H13: 3560
B14: 45028 | C14: 2731032897 | D14: 4 | E14: Ana Luisa Ramos | F14: Radiofrecuencia abdomen, cintura y espalda baja | G14: Visa | H14: 1780
... B59: 45278 | C59: 182013905 | D59: 6 | E59: Betzalia Maribel Arriaga | F59: Radiofrecuencia rostro y cuello | G59: Visa L. | H59: 2670
E60: Total | H60: =SUM(H3:H59) -> 154013

Sheet Ultrasonido
A1: Ultrasonido post-operatorio | B1: Fecha | C1: No. de Factura | D1: Cantidad | E1: Nombre del Paciente | F1: Tratamiento | G1: Forma de Pago | H1: Total
B3: 44981 | C3: 1538738192 | D3: 1 | E3: Luis Francisco Garcia Axulen | F3: Ultrasonido post-operatorio | G3: Deposito | H3: 220
B4: 44987 | C4: 1563968764 | D4: 1 | E4: Luis Francisco Garcia | F4: Abono a ultrasonido post-operatorio | G4: Deposito | H4: 1000
B5: 45002 | C5: 2335131016 | D5: 1 | E5: Blanca Lemus | F5: Ultrasonido post-operatorio | G5: Efectivo | H5: 230
B6: 45030 | C6: 90590367 | D6: 2 | E6: Katherine Portillo | F6: Ultrasonido post-operatorio | G6: Credomatic | H6: 360
B7: 45037 | C7: 2626896055 | D7: 2 | E7: Katherine Portillo | F7: Ultrasonido post-operatorio | G7: Credomatic | H7: 360
B8: 45040 | C8: 1416577598 | D8: 10 | E8: Ana Vriginia Coosemans | F8: Ultrasonido post-operatorio | G8: Deposito | H8: 1200
B9: 45040 | C9: 4087041600 | D9: 5 | E9: Rony Caballero | F9: Ultrasonido post-operatorio | G9: Efectivo | H9: 900
B10: 45042 | C10: 2064532099 | D10: 5 | E10: Rafael Fiallos | F10: Ultrasonido post-operatorio | G10: Efectivo | H10: 600
B11: 45042 | C11: 2064532099 | D11: 5 | E11: Norma Pineda | F11: Ultrasonido post-operatorio | G11: Efectivo | H11: 600
B12: 45048 | C12: 2562475862 | D12: 5 | E12: Sulma Elizabeth Hernandez | F12: Ultrasonidos post-operatorio | G12: Credomatic | H12: 1000
B13: 45048 | C13: 226640767 | D13: 1 | E13: Katherine Portillo | F13: Ultrasonidos post-operatorio | G13: Visa L. | H13: 180
B14: 45055 | C14: 1037452307 | D14: 10 | E14: Bonna Marroquin | F14: Ultrasonidos post-operatorio | G14: Credomatic | H14: 1500
... B37: 45265 | C37: 2714255864 | D37: 9 | E37: Sara Mayorga | F37: Ultradonido post-operatorio | G37: Efectivo | H37: 1620
E38: Total | H38: =SUM(H3:H37) -> 36010

Sheet Velo de acido hialuronico
A1: Velo de acido hialuronico | B1: Fecha | C1: No. de Factura | D1: Cantidad | E1: Nombre del Paciente | F1: Tratamiento | G1: Forma de Pago | H1: Total
B3: 44935 | C3: 3232188127 | D3: 1 | E3: Elizabeth Molina | F3: Velo de acido hialuronico | G3: Credomatic | H3: 600
B4: 44936 | C4: 1634550648 | D4: 1 | E4: Anneliese Wintzer | F4: Velo de acido hialuronico | G4: Credomatic | H4: 650
B5: 44939 | C5: 1251688846 | D5: 1 | E5: Vanessa de Mancilla | F5: Velo de acido hialuronico | G5: Credomatic | H5: 650
B6: 44956 | C6: 3581166546 | D6: 1 | E6: Silvia Patricia Oxon | F6: Velo de acido hialuronico | G6: Credomatic | H6: 650
B7: 44973 | C7: 1258243715 | D7: 1 | E7: Elisa De Gil | F7: Velo de acido hialuronico | G7: Cheque | H7: 650
B8: 45180 | C8: 2241154763 | D8: 1 | E8: Mabby Morales | F8: Velo de acido hialuronico | G8: Credomatic | H8: 650
B9: 45188 | C9: 3045738417 | D9: 3 | E9: Carlos Colindres | F9: Velo de acido hialuronico | G9: Visa L. | H9: 1770
B10: 45188 | C10: 1965903057 | D10: 3 | E10: Heidy Colindres | F10: Velo de acido hialuronico | G10: Visa L. | H10: 1770
B11: 45194 | C11: 2464498696 | D11: 3 | E11: Maria de Leon | F11: Velo de acido hialuronico | G11: Visa | H11: 1770
B12: 45233 | C12: 1711164460 | D12: 1 | E12: Clara Conde | F12: Velo de acido hialuronico | G12: Credomatic | H12: 650
E13: Total | H13: =SUM(H3:H12) -> 9810

Sheet Velox
A1: Velox | B1: Fecha | C1: No. de Factura | D1: Cantidad | E1: Nombre del Paciente | F1: Tratamiento | G1: Forma de Pago | H1: Total
B3: 44931 | C3: 8077385 | D3: 6 | E3: Nicolle Melville | F3: Velox espalda baja, entrepierna, banana roll y chaparrera | G3: Visa | H3: 2856
B4: 45007 | C4: 226118147 | D4: 8 | E4: Danury Samayoa | F4: Velox chaparreras, entrepierna, y banana roll | G4: Visa | H4: 2128
B5: 45041 | C5: 779174422 | D5: 8 | E5: Jose Antonio Arzu | F5: Velox abdomen, cintura y espalda baja | G5: Credomatic | H5: 2500
B6: 45072 | C6: 2444970953 | D6: 8 | E6: Luis Araya | F6: Velox abdomen, cintura, pectoral, espalda | G6: Visa | H6: 2240
B7: 45084 | C7: 2573160404 | D7: 8 | E7: Maria Esperanza Barrutia | F7: Velox abdomen, cintura, chaparrera y banana roll | G7: Credomatic | H7: 2056
B8: 45099 | C8: 3564389051 | D8: 8 | E8: Angelica Maria Giron | F8: Velox abdomen completo, cintura y espalda baja | G8: Credomatic | H8: 4200
B9: 45126 | C9: 3241168669 | D9: 8 | E9: Karla Bocaletti De Enriquez | F9: Velox abdomen, cintura y brazos | G9: Visa | H9: 2688
B10: 45134 | C10: 3419488724 | D10: 8 | E10: Claudia Contreras De Alfaro | F10: Velox chaparrera y entrepierna | G10: Visa | H10: 3840
B11: 45146 | C11: 4165747199 | D11: 6 | E11: Karina Martinez | F11: Velox reductor abdomen y cintura | G11: Visa L. | H11: 2280
B12: 45155 | C12: 3861465003 | D12: 2 | E12: Isabel Figueroa Buezo | F12: Velox abdomen, cintura y gorditos espalda alta | G12: Credomatic | H12: 1000
B13: 45162 | C13: 438585984 | D13: 8 | E13: Karleen Giron | F13: Velox abdomen, banana roll, entrepierna y chaparreras | G13: Deposito | H13: 3000
B14: 45205 | C14: 2987934997 | D14: 8 | E14: Olga Lucia Tercero | F14: Velox abdomen, cintura, chaparrera y banana roll | G14: Deposito | H14: 2320
... B18: 45278 | C18: 461981108 | D18: 8 | E18: Kirin Gangaramani | F18: Velox abdomen, cintura y chaparrera | G18: Visa | H18: 4000
E19: Total | H19: =SUM(H3:H18) -> 39808

Sheet Verju
A1: Verju | B1: Fecha | C1: No. de Factura | D1: Cantidad | E1: Nombre del Paciente | F1: Tratamiento | G1: Forma de Pago | H1: Total
B3: 44937 | C3: 2805746571 | D3: 11 | E3: Maggie Villela | F3: Verju abdomen y cintura | G3: Visa L. | H3: 4576
B4: 44937 | C4: 2805746571 | D4: 1 | E4: Maggie Villela | F4: Verju abdomen y cintura | G4: Visa L. | H4: 424
B5: 44949 | C5: 906906239 | D5: 12 | E5: Rosario Palma Recinos | F5: Verju abdomen y cintura | G5: Visa | H5: 5100
B6: 44960 | C6: 2499104273 | D6: 1 | E6: Ana Lucia Cuestas | F6: Verju abdomen y cintura | G6: Visa L. | H6: 708.33
E7: Total | H7: =SUM(H3:H6) -> 10808.33

Sheet Vitamina C intravenosa
A1: Vitamina C intravenosa | B1: Fecha | C1: No. de Factura | D1: Cantidad | E1: Nombre del Paciente | F1: Tratamiento | G1: Forma de Pago | H1: Total
B3: 44932 | C3: 2848999730 | D3: 1 | E3: Iveth Bojorquez | F3: Aplicación vitamina C intravenosa | G3: Visa | H3: 500
B4: 44935 | C4: 481709657 | D4: 2 | E4: Sonia Chiroy de Rodriguez | F4: Aplicación vitamina C intravenosa | G4: Efectivo | H4: 1000
B5: 44935 | C5: 481709657 | D5: 1 | E5: Josselyn Rodriguez | F5: Aplicación vitamina C intravenosa | G5: Efectivo | H5: 500
B6: 44935 | C6: 1604799877 | D6: 3 | E6: Carlos Humberto Rodriguez | F6: Aplicación vitamina C intravenosa | G6: Deposito | H6: 1500
B7: 44937 | C7: 1511474418 | D7: 1 | E7: Mimi de Quan | F7: Aplicación vitamina C intravenosa | G7: Credomatic | H7: 500
B8: 44938 | C8: 2010334081 | D8: 3 | E8: Karla Pinto Portillo | F8: Aplicación vitamina C intravenosa | G8: Efectivo $ | H8: 1500
B9: 44942 | C9: 3683404304 | D9: 2 | E9: Ninive Vargas | F9: Aplicación vitamina C intravenosa | G9: Credomatic | H9: 1000
B10: 44943 | C10: recibo | D10: 1 | E10: Gricel Chun | F10: Aplicación vitamina C intravenosa | G10: Efectivo | H10: 93.5
B11: 44944 | C11: 467615785 | D11: 1 | E11: Evelyn Hernandez | F11: Aplicación vitamina C intravenosa | G11: Credomatic | H11: 500
B12: 44944 | C12: 1344424017 | D12: 2 | E12: Evelyn Hernandez | F12: Aplicación vitamina C intravenosa | G12: Credomatic | H12: 1000
B13: 44946 | C13: 1937655612 | D13: 1 | E13: Myra Leana Cortez | F13: Aplicación vitamina C intravenosa | G13: Visa | H13: 500
B14: 44946 | C14: 1937655612 | D14: 1 | E14: Katiana Liberona | F14: Aplicación vitamina C intravenosa | G14: Efectivo | H14: 500
B15: 44946 | C15: 4289874178 | D15: 3 | E15: Maria Josee Solares | F15: Aplicación vitamina C intravenosa | G15: Visa L. | H15: 1500
B16: 44949 | C16: 1176912602 | D16: 1 | E16: Viviano Gomez | F16: Aplicación vitamina C intravenosa | G16: Efectivo | H16: 500
B17: 44949 | C17: 1176912602 | D17: 1 | E17: Viviano Gomez (acompañante) | F17: Aplicación vitamina C intravenosa | G17: Efectivo | H17: 500
B18: 44949 | C18: 872106676 | D18: 1 | E18: Blanca Lara | F18: Aplicación vitamina C intravenosa | G18: Visa | H18: 500
B19: 44949 | C19: 872106676 | D19: 1 | E19: Margarita Lara | F19: Aplicación vitamina C intravenosa | G19: Visa | H19: 500
B20: 44949 | C20: 3872804531 | D20: 1 | E20: Karla Sarti De Bonatti | F20: Aplicación vitamina C intravenosa | G20: Credomatic | H20: 500
B21: 44949 | C21: 3086305346 | D21: 1 | E21: Paola Monteagudo | F21: Aplicación vitamina C intravenosa | G21: Efectivo | H21: 500
