Workbook

Sheet PRESENTACIÓN DE RESULTADOS
A1: Tratamiendo | B1: Enero | C1: Febrero | D1: Marzo | E1: Abril | F1: Mayo | G1: Junio | H1: Julio | I1: Agosto | J1: Septiembre | K1: Octubre | L1: Noviembre | M1: Diciembre | N1: Total
A2: Producto | B2: =SUM(Producto!H3:H9) -> 4962 | C2: =SUM(Producto!H10:H36) -> 21362 | D2: =SUM(Producto!H37:H71) -> 26779.25 | E2: =SUM(Producto!H72:H85) -> 11890 | F2: =SUM(Producto!H86:H112) -> 19710 | G2: =SUM(Producto!H113:H142) -> 18333.2 | H2: =SUM(Producto!H143:H184) -> 28450 | I2: =SUM(Producto!H185:H211) -> 17615 | J2: =SUM(Producto!H212:H223) -> 8075 | K2: =SUM(Producto!H224:H241) -> 12795 | L2: =SUM(Producto!H242:H285) -> 34653.77 | M2: =SUM(Producto!H286:H299) -> 8580 | N2: =SUM(B2:M2) -> 213205.22 | O2: =+Producto!H300 -> 213205.22 | P2: =+O2-N2 -> 0
A3: Acido hialuronico | B3: =SUM('Acido hialuronico'!H3) -> 2800 | C3: =SUM('Acido hialuronico'!H4:H6) -> 13900 | D3: =SUM('Acido hialuronico'!H7:H9) -> 8100 | E3: 0 | F3: =SUM('Acido hialuronico'!H10:H11) -> 10600 | G3: =SUM('Acido hialuronico'!H12:H15) -> 14000 | H3: =SUM('Acido hialuronico'!H16) -> 2800 | I3: 0 | J3: =SUM('Acido hialuronico'!H17:H20) -> 15600 | K3: =SUM('Acido hialuronico'!H21:H25) -> 19004 | L3: =SUM('Acido hialuronico'!H26) -> 9450 | M3: =SUM('Acido hialuronico'!H27) -> 3150 | N3: =SUM(B3:M3) -> 99404 | O3: =+'Acido hialuronico'!H28 -> 99404 | P3: =+O3-N3 -> 0
A4: Depilación | B4: =SUM(Depilación!H3:H10) -> 7425 | C4: =SUM(Depilación!H11) -> 266 | D4: =SUM(Depilación!H12:H17) -> 4580 | E4: =SUM(Depilación!H18:H30) -> 9267 | F4: =SUM(Depilación!H31) -> 925 | G4: =SUM(Depilación!H32:H39) -> 4379 | H4: =SUM(Depilación!H40:H48) -> 7229 | I4: =SUM(Depilación!H49:H51) -> 2875 | J4: =SUM(Depilación!H52:H63) -> 10550 | K4: =SUM(Depilación!H64:H65) -> 1625 | L4: =SUM(Depilación!H66:H84) -> 15887.5 | M4: =SUM(Depilación!H85:H96) -> 9354 | N4: =SUM(B4:M4) -> 74362.5 | O4: =+Depilación!H97 -> 74362.5 | P4: =+O4-N4 -> 0
A5: Emsculpt | B5: 0 | C5: 0 | D5: 0 | E5: =SUM(Emsculpt!H3) -> 7500 | F5: 0 | G5: =SUM(Emsculpt!H4) -> 7500 | H5: 0 | I5: 0 | J5: 0 | K5: 0 | L5: 0 | M5: 0 | N5: =SUM(B5:M5) -> 15000 | O5: =+Emsculpt!H5 -> 15000 | P5: =+O5-N5 -> 0
A6: Emtone | B6: =SUM(Emtone!H3:H6) -> 20000 | C6: =SUM(Emtone!H7:H9) -> 11250 | D6: =SUM(Emtone!H10) -> 5000 | E6: =SUM(Emtone!H11) -> 5000 | F6: =SUM(Emtone!H12) -> 5000 | G6: =SUM(Emtone!H13:H15) -> 13750 | H6: =SUM(Emtone!H16:H19) -> 20000 | I6: =SUM(Emtone!H20:H21) -> 10000 | J6: =SUM(Emtone!H22:H23) -> 10000 | K6: =SUM(Emtone!H24:H25) -> 10000 | L6: 0 | M6: =SUM(Emtone!H26) -> 5000 | N6: =SUM(B6:M6) -> 115000 | O6: =+Emtone!H27 -> 115000 | P6: =+O6-N6 -> 0
A7: Exilis | B7: =SUM(Exilis!H3:H5) -> 19500 | C7: =SUM(Exilis!H6:H17) -> 50900 | D7: =SUM(Exilis!H18:H22) -> 32500 | E7: =SUM(Exilis!H23:H30) -> 42800 | F7: =SUM(Exilis!H31:H34) -> 29250 | G7: =SUM(Exilis!H35:H41) -> 27100.01 | H7: =SUM(Exilis!H42:H50) -> 28025 | I7: =SUM(Exilis!H51:H55) -> 23300 | J7: =SUM(Exilis!H56:H63) -> 40300 | K7: =SUM(Exilis!H64:H66) -> 7050 | L7: =SUM(Exilis!H67:H73) -> 38000 | M7: =SUM(Exilis!H74:H77) -> 14100 | N7: =SUM(B7:M7) -> 352825.01 | O7: =+Exilis!H78 -> 352825.01 | P7: =+O7-N7 -> 0
A8: Exfoliación | B8: 0 | C8: 0 | D8: 0 | E8: =SUM(Exfoliación!H3:H4) -> 700 | F8: =SUM(Exfoliación!H5) -> 200 | G8: =SUM(Exfoliación!H6) -> 350 | H8: 0 | I8: 0 | J8: 0 | K8: 0 | L8: 0 | M8: 0 | N8: =SUM(B8:M8) -> 1250 | O8: =+Exfoliación!H7 -> 1250 | P8: =+O8-N8 -> 0
A9: Facial purificante | B9: =SUM('Facial purificante'!H3:H4) -> 977.5 | C9: =SUM('Facial purificante'!H5:H12) -> 4425 | D9: =SUM('Facial purificante'!H13:H17) -> 4269 | E9: =SUM('Facial purificante'!H18:H19) -> 1150 | F9: =SUM('Facial purificante'!H20:H27) -> 4925 | G9: =SUM('Facial purificante'!H28:H30) -> 1553 | H9: =SUM('Facial purificante'!H31:H35) -> 3360 | I9: =SUM('Facial purificante'!H36:H41) -> 3726 | J9: =SUM('Facial purificante'!H42:H44) -> 4150 | K9: =SUM('Facial purificante'!H45:H48) -> 3497.5 | L9: =SUM('Facial purificante'!H49:H52) -> 2682.5 | M9: =SUM('Facial purificante'!H53:H57) -> 4020 | N9: =SUM(B9:M9) -> 38735.5 | O9: =+'Facial purificante'!H58 -> 38735.5 | P9: =+O9-N9 -> 0
A10: Hifu microson | B10: 0 | C10: 0 | D10: 0 | E10: 0 | F10: 0 | G10: 0 | H10: 0 | I10: 0 | J10: 0 | L10: 0 | M10: 0 | N10: =SUM(B10:M10) -> 0 | O10: =+Hifu!H4 -> 0 | P10: =+O10-N10 -> 0
A11: Hydrafacial | B11: =SUM(Hydrafacial!H3:H6) -> 5800 | C11: =SUM(Hydrafacial!H7:H8) -> 1484 | D11: =SUM(Hydrafacial!H9:H10) -> 1934 | E11: =SUM(Hydrafacial!H11:H15) -> 4636 | F11: =SUM(Hydrafacial!H16:H23) -> 12393.399 | G11: =SUM(Hydrafacial!H24:H27) -> 3700.98 | H11: =SUM(Hydrafacial!H28:H31) -> 2934 | I11: =SUM(Hydrafacial!H32:H37) -> 5004 | J11: 0 | K11: =SUM(Hydrafacial!H38:H40) -> 4674 | L11: =SUM(Hydrafacial!H41:H50) -> 12855 | M11: =SUM(Hydrafacial!H51) -> 1334 | N11: =SUM(B11:M11) -> 56749.379 | O11: =+Hydrafacial!H52 -> 56749.379 | P11: =+O11-N11 -> 0
A12: Laboratorios | B12: 0 | C12: 0 | D12: 0 | E12: 0 | F12: 0 | G12: 0 | H12: 0 | I12: 0 | J12: 0 | K12: =SUM(Laboratorios!H3) -> 950 | L12: =SUM(Laboratorios!H4) -> 950 | M12: 0 | N12: =SUM(B12:M12) -> 1900 | O12: =+Laboratorios!H5 -> 1900 | P12: =+O12-N12 -> 0
A13: Masaje linfatico | B13: =SUM('Masaje linfatico'!H3:H4) -> 500 | C13: =SUM('Masaje linfatico'!H5) -> 800 | D13: =SUM('Masaje linfatico'!H6:H7) -> 2000 | E13: =SUM('Masaje linfatico'!H8:H11) -> 3400 | F13: =SUM('Masaje linfatico'!H12:H14) -> 5000 | G13: =SUM('Masaje linfatico'!H15:H17) -> 2200 | H13: =SUM('Masaje linfatico'!H18:H20) -> 5600 | I13: 0 | J13: =SUM('Masaje linfatico'!H21:H26) -> 4050 | K13: =SUM('Masaje linfatico'!H27) -> 2000 | L13: =SUM('Masaje linfatico'!H28:H30) -> 5000 | M13: =SUM('Masaje linfatico'!H31) -> 1000 | N13: =SUM(B13:M13) -> 31550 | O13: =+'Masaje linfatico'!H32 -> 31550 | P13: =+O13-N13 -> 0
A14: Mesoterapia | B14: 0 | C14: =SUM(Mesoterapia!H3:H10) -> 17912 | D14: =SUM(Mesoterapia!H11:H20) -> 23800 | E14: =SUM(Mesoterapia!H21:H26) -> 27200 | F14: =SUM(Mesoterapia!H27:H29) -> 2800 | G14: =SUM(Mesoterapia!H30:H31) -> 6730 | H14: =SUM(Mesoterapia!H32:H33) -> 6749.9999 | I14: =SUM(Mesoterapia!H34) -> 4800 | J14: =SUM(Mesoterapia!H35:H42) -> 11735 | K14: 0 | L14: =SUM(Mesoterapia!H43:H44) -> 9900 | M14: 0 | N14: =SUM(B14:M14) -> 111627 | O14: =+Mesoterapia!H45 -> 111627 | P14: =+O14-N14 -> 0
A15: Morpheus | B15: =SUM(Morpheus!H3:H18) -> 160000 | C15: =SUM(Morpheus!H19:H33) -> 150000 | D15: =SUM(Morpheus!H34:H43) -> 95000 | E15: =SUM(Morpheus!H44:H52) -> 116200 | F15: =SUM(Morpheus!H53:H64) -> 130000 | G15: =SUM(Morpheus!H65:H73) -> 105000 | H15: =SUM(Morpheus!H74:H83) -> 100000 | I15: =SUM(Morpheus!H84:H90) -> 70000 | J15: =SUM(Morpheus!H91:H100) -> 95000 | K15: =SUM(Morpheus!H101:H111) -> 97000 | L15: =SUM(Morpheus!H112:H117) -> 55000 | M15: =SUM(Morpheus!H118:H126) -> 95000 | N15: =SUM(B15:M15) -> 1268200 | O15: =+Morpheus!H127 -> 1268200 | P15: =+O15-N15 -> 0
A16: Pico-láser | B16: 0 | C16: 0 | D16: 0 | E16: 0 | F16: 0 | G16: 0 | H16: 0 | I16: 0 | J16: 0 | K16: 0 | L16: 0 | M16: 0 | N16: =SUM(B16:M16) -> 0 | O16: =+'Pico-láser'!H4 -> 0 | P16: =+O16-N16 -> 0
A17: Profhilo | B17: =SUM(Profhilo!H3:H13) -> 46500 | C17: =SUM(Profhilo!H14:H18) -> 22500 | D17: =SUM(Profhilo!H19:H27) -> 36000 | E17: =SUM(Profhilo!H28:H33) -> 27500 | F17: =SUM(Profhilo!H34:H42) -> 42500 | G17: =SUM(Profhilo!H43:H47) -> 22500 | H17: =SUM(Profhilo!H48:H57) -> 47500 | I17: =SUM(Profhilo!H58:H64) -> 28400 | J17: =SUM(Profhilo!H65:H69) -> 18900 | K17: 0 | L17: =SUM(Profhilo!H70) -> 3200 | M17: =SUM(Profhilo!H71:H78) -> 35650 | N17: =SUM(B17:M17) -> 331150 | O17: =+Profhilo!H79 -> 331150 | P17: =+O17-N17 -> 0
A18: PRP | B18: =SUM(PRP!H3:H9) -> 14888 | C18: =SUM(PRP!H10:H17) -> 28800 | D18: =SUM(PRP!H18:H27) -> 24340 | E18: =SUM(PRP!H28:H35) -> 18899.998 | F18: =SUM(PRP!H36:H60) -> 46200 | G18: =SUM(PRP!H61:H64) -> 8600 | H18: =SUM(PRP!H65:H73) -> 21800 | I18: =SUM(PRP!H74:H81) -> 15850 | J18: =SUM(PRP!H82:H92) -> 24599.999 | K18: =SUM(PRP!H93:H109) -> 42249.996 | L18: =SUM(PRP!H110:H120) -> 37265 | M18: =SUM(PRP!H121:H124) -> 6260 | N18: =SUM(B18:M18) -> 289752.99 | O18: =+PRP!H125 -> 289752.99 | P18: =+O18-N18 -> 0
A19: Radiofrecuencia | B19: =SUM(Radiofrecuencia!H3:H4) -> 6204 | C19: =SUM(Radiofrecuencia!H5:H10) -> 15028 | D19: =SUM(Radiofrecuencia!H11:H13) -> 5200 | E19: =SUM(Radiofrecuencia!H14) -> 3000 | F19: =SUM(Radiofrecuencia!H15:H20) -> 16250 | G19: =SUM(Radiofrecuencia!H21) -> 3560 | H19: =SUM(Radiofrecuencia!H22:H27) -> 14600 | I19: =SUM(Radiofrecuencia!H28:H29) -> 7260 | J19: =SUM(Radiofrecuencia!H30:H32) -> 9375 | K19: =SUM(Radiofrecuencia!H33:H36) -> 13189.996 | L19: =SUM(Radiofrecuencia!H37:H45) -> 25900 | M19: =SUM(Radiofrecuencia!H46:H47) -> 6471 | N19: =SUM(B19:M19) -> 126038 | O19: =+Radiofrecuencia!H48 -> 126038 | P19: =+O19-N19 -> 0
A20: Ultrasonido | B20: =SUM(Ultrasonido!H3) -> 900 | C20: =SUM(Ultrasonido!H4:H7) -> 960 | D20: 0 | E20: =SUM(Ultrasonido!H8:H9) -> 2000 | F20: 0 | G20: =SUM(Ultrasonido!H10) -> 1000 | H20: =SUM(Ultrasonido!H11:H12) -> 2080 | I20: =SUM(Ultrasonido!H13:H15) -> 5000 | J20: =SUM(Ultrasonido!H16:H18) -> 3060 | K20: =SUM(Ultrasonido!H19) -> 1000 | L20: =SUM(Ultrasonido!H20) -> 2000 | M20: =SUM(Ultrasonido!H21:H22) -> 1800 | N20: =SUM(B20:M20) -> 19800 | O20: =+Ultrasonido!H23 -> 19800 | P20: =+O20-N20 -> 0
A21: Velo de acido hialuronico | B21: 0 | C21: 0 | D21: 0 | E21: 0 | F21: 0 | G21: 0 | H21: 0 | I21: 0 | J21: 0 | K21: 0 | L21: 0 | M21: 0 | N21: =SUM(B21:M21) -> 0 | O21: =+'Velo de acido hialuronico'!H4 -> 0 | P21: =+O21-N21 -> 0
A22: Velox | B22: 0 | C22: 0 | D22: 0 | E22: 0 | F22: 0 | G22: 0 | H22: 0 | I22: 0 | J22: 0 | K22: 0 | L22: 0 | M22: 0 | N22: =SUM(B22:M22) -> 0 | O22: =+Velox!H4 -> 0 | P22: =+O22-N22 -> 0
A23: Vitamina C intravenosa | B23: =SUM('Vitamina C intravenosa'!H3:H12) -> 7131 | C23: =SUM('Vitamina C intravenosa'!H13:H26) -> 12305 | D23: =SUM('Vitamina C intravenosa'!H27:H34) -> 10006 | E23: =SUM('Vitamina C intravenosa'!H35:H43) -> 7866 | F23: =SUM('Vitamina C intravenosa'!H44:H66) -> 28766.48 | G23: =SUM('Vitamina C intravenosa'!H67:H78) -> 13375 | H23: =SUM('Vitamina C intravenosa'!H79:H84) -> 8261.9998 | I23: =SUM('Vitamina C intravenosa'!H85:H96) -> 13216 | J23: =SUM('Vitamina C intravenosa'!H97:H106) -> 11611 | K23: =SUM('Vitamina C intravenosa'!H107:H120) -> 12840 | L23: =SUM('Vitamina C intravenosa'!H121:H129) -> 9471 | M23: =SUM('Vitamina C intravenosa'!H130:H138) -> 9630 | N23: =SUM(B23:M23) -> 144479.48 | O23: =+'Vitamina C intravenosa'!H139 -> 144479.48 | P23: =+O23-N23 -> 0
A24: Ciclo coolsculpting | B24: 0 | C24: 0 | D24: 0 | E24: =SUM('Ciclo coolsculpting'!H3:H4) -> 18000 | F24: 0 | G24: 0 | H24: 0 | I24: 0 | J24: 0 | K24: 0 | L24: 0 | M24: 0 | N24: =SUM(B24:M24) -> 18000 | O24: =+'Ciclo coolsculpting'!H5 -> 18000 | P24: =+O24-N24 -> 0
A25: Dermapen | B25: 0 | C25: =SUM(Dermapen!H3) -> 1300 | D25: 0 | E25: 0 | F25: 0 | G25: =SUM(Dermapen!H4:H5) -> 3000 | H25: 0 | I25: =SUM(Dermapen!H6:H9) -> 8600 | J25: =SUM(Dermapen!H10:H11) -> 7200 | K25: =SUM(Dermapen!H12:H15) -> 9300 | L25: =SUM(Dermapen!H16:H20) -> 13400 | M25: =SUM(Dermapen!H21:H22) -> 3200 | N25: =SUM(B25:M25) -> 46000 | O25: =+Dermapen!H23 -> 46000 | P25: =+O25-N25 -> 0
A26: Láser CO2 | B26: 0 | C26: 0 | D26: 0 | E26: 0 | F26: =SUM('Láser CO2'!H3) -> 5000 | G26: 0 | H26: 0 | I26: =SUM('Láser CO2'!H4) -> 5600 | J26: 0 | K26: 0 | L26: =SUM('Láser CO2'!H5:H6) -> 12000 | M26: 0 | N26: =SUM(B26:M26) -> 22600 | O26: =+'Láser CO2'!H7 -> 22600 | P26: =+O26-N26 -> 0
A27: Masaje relajante | B27: 0 | C27: 0 | D27: =SUM('Masaje relajante'!H3:H6) -> 6700 | E27: 0 | F27: =SUM('Masaje relajante'!H7:H9) -> 2450 | G27: 0 | H27: =SUM('Masaje relajante'!H10) -> 4000 | I27: =SUM('Masaje relajante'!H11:H12) -> 4000 | J27: =SUM('Masaje relajante'!H13) -> 250 | K27: =SUM('Masaje relajante'!H14) -> 4000 | L27: 0 | M27: =SUM('Masaje relajante'!H15) -> 2000 | N27: =SUM(B27:M27) -> 23400 | O27: =+'Masaje relajante'!H16 -> 23400 | P27: =+O27-N27 -> 0
A28: Oligoelementos | B28: 0 | C28: 0 | D28: 0 | E28: 0 | F28: 0 | G28: 0 | H28: 0 | I28: 0 | J28: =SUM(Oligoelementos!H3) -> 1995 | K28: =SUM(Oligoelementos!H4) -> 700 | L28: =SUM(Oligoelementos!H5) -> 1395 | M28: 0 | N28: =SUM(B28:M28) -> 4090 | O28: =+Oligoelementos!H6 -> 4090 | P28: =+O28-N28 -> 0
A29: Grow | B29: =SUM(Grow!H3:H6) -> 9112.09 | C29: =SUM(Grow!H7:H10) -> 8912.09 | D29: =SUM(Grow!H11:H13) -> 7912.09 | E29: =SUM(Grow!H14:H16) -> 7912.09 | F29: =SUM(Grow!H17:H19) -> 7912.09 | G29: =SUM(Grow!H20:H22) -> 7912.09 | H29: =SUM(Grow!H23:H26) -> 8912.09 | I29: =SUM(Grow!H27:H29) -> 7912.09 | J29: =SUM(Grow!H30:H32) -> 7912.09 | K29: =SUM(Grow!H33:H36) -> 9412.09 | L29: 0 | M29: =SUM(Grow!H37:H42) -> 15824.18 | N29: =SUM(B29:M29) -> 99645.08 | O29: =+Grow!H43 -> 99645.08 | P29: =+O29-N29 -> 0
A30: Abonos | B30: 0 | C30: 0 | D30: 0 | E30: 0 | F30: 0 | G30: 0 | H30: 0 | I30: 0 | J30: =SUM('Abonos a tratamientos'!H3:H4) -> 90 | K30: 0 | L30: =SUM('Abonos a tratamientos'!H5) -> 30 | M30: 0 | N30: =SUM(B30:M30) -> 120 | O30: =+'Abonos a tratamientos'!H6 -> 120 | P30: =+O30-N30 -> 0
A31: Celulas madre | B31: 0 | C31: 0 | D31: 0 | E31: 0 | F31: 0 | G31: 0 | H31: 0 | I31: 0 | J31: 0 | K31: =SUM('Celulas madre'!H3) -> 19050 | L31: =SUM('Celulas madre'!H4) -> 19050 | M31: 0 | N31: =SUM(B31:M31) -> 38100 | O31: =+'Celulas madre'!H5 -> 38100 | P31: =+O31-N31 -> 0
A32: Peeling | B32: 0 | C32: 0 | D32: =SUM(Peeling!H3) -> 1800 | E32: 0 | F32: 0 | G32: =SUM(Peeling!H4:H6) -> 6850 | H32: =SUM(Peeling!H7) -> 849.999 | I32: 0 | J32: =SUM(Peeling!H8:H9) -> 2190 | K32: =SUM(Peeling!H10) -> 1800 | L32: 0 | M32: 0 | N32: =SUM(B32:M32) -> 13489.999 | O32: =+Peeling!H11 -> 13489.999 | P32: =+O32-N32 -> 0
A33: Spectra ginecologico | B33: =SUM('Spectra ginecologico'!H3:H4) -> 10000 | C33: 0 | D33: 0 | E33: 0 | F33: =SUM('Spectra ginecologico'!H5) -> 5000 | G33: =SUM('Spectra ginecologico'!H6) -> 5500 | H33: 0 | I33: =SUM('Spectra ginecologico'!H7) -> 5000 | J33: 0 | K33: 0 | L33: 0 | M33: 0 | N33: =SUM(B33:M33) -> 25500 | O33: =+'Spectra ginecologico'!H8 -> 25500 | P33: =+O33-N33 -> 0
A34: Elimación de lunares | B34: 0 | C34: 0 | D34: 0 | E34: 0 | F34: 0 | G34: 0 | H34: 0 | I34: 0 | J34: 0 | K34: 0 | L34: 0 | M34: 0 | N34: =SUM(B34:M34) -> 0 | O34: =+'Eliminación de lunares'!H4:H4 -> 0 | P34: =+O34-N34 -> 0
A35: Botox | B35: 0 | C35: 0 | D35: =SUM(Botox!H3:H120) -> 254972.99 | E35: 0 | F35: 0 | G35: 0 | H35: =SUM(Botox!H121:H228) -> 264220 | I35: 0 | J35: =SUM(Botox!H229:H231) -> 10835 | K35: =SUM(Botox!H232:H233) -> 1935 | L35: =SUM(Botox!H234:H364) -> 311523.99 | M35: 0 | N35: =SUM(B35:M35) -> 843486.98 | O35: =+Botox!H365 -> 843486.98 | P35: =+O35-N35 -> 0
A36: Encimas | B36: 0 | C36: 0 | D36: 0 | E36: 0 | F36: 0 | G36: 0 | H36: 0 | I36: 0 | J36: 0 | K36: 0 | L36: 0 | M36: 0 | N36: =SUM(B36:M36) -> 0 | O36: =+Encimas!H4 -> 0 | P36: =+O36-N36 -> 0
A37: Cambio de tratamiento | B37: 0 | C37: =SUM('Cambio de tratamiento'!H3) -> 215 | D37: 0 | E37: 0 | F37: 0 | G37: =SUM('Cambio de tratamiento'!H4:H5) -> 430 | H37: =SUM('Cambio de tratamiento'!H6) -> 834 | I37: 0 | J37: 0 | K37: 0 | L37: =SUM('Cambio de tratamiento'!H7) -> 800 | M37: 0 | N37: =SUM(B37:M37) -> 2279 | O37: =+'Cambio de tratamiento'!H8 -> 2279 | P37: =+O37-N37 -> 0
A38: Microdermoabrasión | B38: 0 | C38: 0 | D38: =SUM(Microdermoabrasión!H3) -> 350 | E38: 0 | F38: 0 | G38: 0 | H38: 0 | I38: 0 | J38: 0 | K38: =SUM(Microdermoabrasión!H4) -> 350 | L38: 0 | M38: 0 | N38: =SUM(B38:M38) -> 700 | O38: =+Microdermoabrasión!H5 -> 700 | P38: =+O38-N38 -> 0
A39: Terapia Luminica | B39: 0 | C39: 0 | D39: 0 | E39: 0 | F39: =SUM('Terapia Luminica'!H3) -> 300 | G39: 0 | H39: 0 | I39: 0 | J39: 0 | K39: 0 | L39: 0 | M39: 0 | N39: =SUM(B39:M39) -> 300 | O39: =+'Terapia Luminica'!H4 -> 300 | P39: =+O39-N39 -> 0
A40: Oscilacion | B40: =SUM(Oscilación!H3:H6) -> 4250 | C40: =SUM(Oscilación!H7) -> 5000 | D40: 0 | E40: =SUM(Oscilación!H8:H10) -> 7500 | F40: =SUM(Oscilación!H11:H12) -> 4500 | G40: =SUM(Oscilación!H13:H18) -> 14000 | H40: =SUM(Oscilación!H19:H20) -> 6500 | I40: =SUM(Oscilación!H21:H28) -> 24000 | J40: =SUM(Oscilación!H29:H37) -> 21500 | K40: =SUM(Oscilación!H38:H44) -> 11000 | L40: =SUM(Oscilación!H45:H49) -> 11000 | M40: =SUM(Oscilación!H50:H56) -> 16500 | N40: =SUM(B40:M40) -> 125750 | O40: =+Oscilación!H57 -> 125750 | P40: =+O40-N40 -> 0
...

Sheet Producto
A1: Producto | B1: Fecha | C1: No. de Factura | D1: Cantidad | E1: Nombre del Paciente | F1: Tratamiento | G1: Forma de Pago | H1: Total
B3: 45666 | C3: 3619245563 | D3: 1 | E3: Claudia Maria De Leon | F3: Beauty collagen advanced (Protocol) | G3: Visa | H3: 850
B4: 45670 | C4: 75580753 | D4: 1 | E4: Patricia Galvez | F4: Dabalash | G4: Credomatic | H4: 999
B5: 45671 | C5: 3937813574 | D5: 1 | E5: Norma De Barquin | F5: Beauty collagen advanced (Protocol) | G5: Visa | H5: 850
B6: 45673 | C6: 3707455606 | D6: 1 | E6: Telma Maldonado | F6: Cancelación Dabalash | G6: Visa | H6: 629
B7: 45673 | C7: 3707455606 | D7: 1 | E7: Telma Maldonado | F7: Mascara by DabaLash | G7: Visa | H7: 250
B8: 45679 | C8: 3971368440 | D8: 1 | E8: Lucia Torres | F8: Dabalash | G8: Credomatic | H8: 999
B9: 45684 | C9: 187779292 | D9: 1 | E9: Wendy Gonzalez | F9: Urea 10% loción reparadora BABÉ | G9: Credomatic | H9: 385
B10: 45694 | C10: 1438207168 | D10: 1 | E10: Teresa Pineda | F10: Fillerina 12 HA - / Desifying filler | G10: Visa | H10: 1850
B11: 45698 | C11: 3050456529 | D11: 2 | E11: Hilda Violeta Peralta | F11: Hyperoil gel tubo 30ml | G11: Credomatic | H11: 600
B12: 45699 | C12: 384060451 | D12: 1 | E12: Heidi Garcia | F12: Fillerina 12 HA - / Desifying filler | G12: Visa | H12: 1850
B13: 45699 | C13: 2503757726 | D13: 1 | E13: Patricia Vila De Mejicanos | F13: Crema nutritiva tensage (ENDOCARE) | G13: Credomatic | H13: 650
B14: 45699 | C14: 2503757726 | D14: 1 | E14: Patricia Vila De Mejicanos | F14: Beauty collagen advanced (protocol) | G14: Credomatic | H14: 850
... B270: 45981 | C270: 2460765672 | D270: 1 | E270: Antonella Ricci | F270: Fillerina 12HA Densifying nigth cream grado 3 | G270: Visa | H270: 1199
B271: 45981 | C271: 2460765672 | D271: 1 | E271: Antonella Ricci | F271: 83295399 | G271: Visa | H271: 1098
B272: 45981 | C272: 2460765672 | D272: 1 | E272: Antonella Ricci | F272: Fillerina 12HA -/ Densifying eye contour cream 3 | G272: Visa | H272: 1000
B273: 45981 | C273: 2456438400 | D273: 1 | E273: Delia Chour | F273: BLOQUEADOR TIZO PHOTOCEUTICAL AM REPLENISH TINDED | G273: Credomatic | H273: 500
B274: 45981 | C274: 1254903775 | D274: 1 | E274: Olga Garcia Pantaleon | F274: BLOQUEADOR TIZO ultra zinc- TINTED | G274: Credomatic | H274: 500
B275: 45981 | C275: 3568518469 | D275: 1 | E275: Irit Azar Samayoa | F275: Fillerina cleansing white clay clarifying mask | G275: Credomatic | H275: 999
B276: 45981 | C276: 3568518469 | D276: 1 | E276: Irit Azar Samayoa | F276: Fillerina 12HA Densifying nigth cream grado 3 | G276: Credomatic | H276: 999
B277: 45981 | C277: 3568518469 | D277: 1 | E277: Irit Azar Samayoa | F277: Fillerina cleansing purifying natural scrub | G277: Credomatic | H277: 930
B278: 45981 | C278: 3568518469 | D278: 1 | E278: Irit Azar Samayoa | F278: protector solar gel oil-free 360 (Heliocare) | G278: Credomatic | H278: 549.77
B279: 45982 | C279: 419513487 | D279: 1 | E279: Ingrid Brolo | F279: Booster renovador intensivo (Germaine de capuccini cod 370012) | G279: Credomatic | H279: 575
B280: 45982 | C280: 4053617566 | D280: 1 | E280: Rossana Vesco | F280: BLOQUEADOR TIZO PHOTOCEUTICAL AM REPLENISH TINDED | G280: Credomatic | H280: 500
B281: 45985 | C281: 1671972613 | D281: 1 | E281: Fidel Santos | F281: Radiance C + pure concetrado 15ml (Germaine) | G281: Deposito | H281: 580
B282: 45985 | C282: 1671972613 | D282: 2 | E282: Fidel Santos | F282: Beauty collagen (protocol advanced) | G282: Deposito | H282: 1500
B283: 45985 | C283: 1671972613 | D283: 2 | E283: Fidel Santos | F283: Proto-col radiance collagen | G283: Deposito | H283: 1180
... B299: 46009 | C299: 2992196965 | D299: 1 | E299: Rinna Maria Mejia Romero | F299: Tea Tree serum | G299: Credomatic | H299: 200
E300: Total | H300: =SUM(H3:H299) -> 213205.22

Sheet Acido hialuronico
A1: Acido hialuronico | B1: Fecha | C1: No. de Factura | D1: Cantidad | E1: Nombre del Paciente | F1: Tratamiento | G1: Forma de Pago | H1: Total
B3: 45670 | C3: 1584874036 | D3: 1 | E3: Claudia Chinchilla | F3: Aplicación de acido hialuronico | G3: Visa | H3: 2800
B4: 45700 | C4: 1742293672 | D4: 1 | E4: Teresa Pineda | F4: Aplicación acido hialuronico labios | G4: Credomatic | H4: 2800
B5: 45701 | C5: 3569110488 | D5: 2 | E5: Ruth Sazo | F5: Aplicación acido hialuronico manos | G5: Visa | H5: 5600
B6: 45706 | C6: 3552724814 | D6: 2 | E6: Ana Lucrecia Garcia | F6: Aplicación acido hialuronico | G6: Visa | H6: 5500
B7: 45722 | C7: 3979231340 | D7: 1 | E7: Johana Ajin Chamale | F7: Aplicación acido hialuronico labios | G7: Visa L. | H7: 2800
B8: 45733 | C8: 352800455 | D8: 1 | E8: Ana Lucrecia Garcia | F8: Aplicación acido hialuronico labios | G8: Credomatic | H8: 2800
B9: 45733 | C9: 352800455 | D9: 1 | E9: Ana Lucrecia Garcia | F9: Aplicación acido hialuronico manos | G9: Credomatic | H9: 2500
B10: 45790 | C10: 1588610819 | D10: 2 | E10: Anabella Dominguez de Franco | F10: Aplicación acido hialuronico manos | G10: Visa | H10: 5000
B11: 45807 | C11: 1849510375 | D11: 2 | E11: Ruth Sazo | F11: Aplicación acido hialuronico manos | G11: Visa | H11: 5600
B12: 45819 | C12: 3729214098 | D12: 1 | E12: Astrid Ordoñez | F12: Aplicación acido hialuronico labios | G12: Visa | H12: 2800
B13: 45819 | C13: 850674363 | D13: 1 | E13: Melina Fischer Bolaños | F13: Aplicación acido hialuronico labios | G13: Credomatic | H13: 2800
B14: 45833 | C14: 3660595390 | D14: 2 | E14: Alcira Echeverria De Torres | F14: Aplicación acido hialuronico | G14: Visa | H14: 5600
... B27: 46001 | C27: 1615613178 | D27: 1 | E27: Dulce Luna Hernandez | F27: Aplicación acido hialuronico labios | G27: Visa | H27: 3150
E28: Total | H28: =SUM(H3:H27) -> 99404

Sheet Depilación
A1: Depilación | B1: Fecha | C1: No. de Factura | D1: Cantidad | E1: Nombre del Paciente | F1: Tratamiento | G1: Forma de Pago | H1: Total
B3: 45667 | C3: 3286452906 | D3: 4 | E3: Vivian Flores | F3: Depilación bikini | G3: Deposito | H3: 925
B4: 45667 | C4: 3286452906 | D4: 4 | E4: Vivian Flores | F4: Depilación axila | G4: Deposito | H4: 700
B5: 45670 | C5: 1920352681 | D5: 4 | E5: Carla De Zelaya | F5: Depilación piernas | G5: Credomatic | H5: 1250
B6: 45670 | C6: 1920352681 | D6: 4 | E6: Carla De Zelaya | F6: Depilación axila | G6: Credomatic | H6: 700
B7: 45670 | C7: 1920352681 | D7: 4 | E7: Carla De Zelaya | F7: Depilación bikini | G7: Credomatic | H7: 975
B8: 45674 | C8: 3478801301 | D8: 4 | E8: Leslie Esposito | F8: Depilación axila | G8: Efectivo | H8: 700
B9: 45674 | C9: 3478801301 | D9: 4 | E9: Leslie Esposito | F9: Depilación bikini | G9: Efectivo | H9: 925
B10: 45674 | C10: 3478801301 | D10: 4 | E10: Leslie Esposito | F10: Depilación piernas | G10: Efectivo | H10: 1250
B11: 45706 | C11: 422527388 | D11: 1 | E11: Julio Matheu | F11: Depilación barbilla y bigote | G11: Visa | H11: 266
B12: 45720 | C12: 327306954 | D12: 4 | E12: Norma De Barquin | F12: Depilación | G12: Credomatic | H12: 480
B13: 45727 | C13: 3985915992 | D13: 4 | E13: Alejandra Quinto | F13: Depilación bikini | G13: Credomatic | H13: 975
B14: 45733 | C14: 1108558680 | D14: 4 | E14: Debbie Richter | F14: Depilación bigote | G14: Credomatic | H14: 750
... B38: 45825 | C38: 2508145774 | D38: 4 | E38: Rita De Castillo | F38: Depilación bigote | G38: Credomatic | H38: 600
B39: 45834 | C39: 642206101 | D39: 1 | E39: Julio Matheu | F39: Depilación bigote y menton | G39: Credomatic | H39: 266
B40: 45860 | C40: 265962801 | D40: 4 | E40: Jose Antonio Arzu | F40: Depilación barba y cuello | G40: Visa L. | H40: 900
B41: 45862 | C41: 171067031 | D41: 4 | E41: Camila Sandoval | F41: Depilación piernas | G41: Credomatic | H41: 1250
B42: 45862 | C42: 171067031 | D42: 4 | E42: Camila Sandoval | F42: Depilación brazos | G42: Credomatic | H42: 1250
B43: 45862 | C43: 171067031 | D43: 4 | E43: Camila Sandoval | F43: Depilación axila | G43: Credomatic | H43: 700
B44: 45862 | C44: 1577667912 | D44: 1 | E44: Marilu Pierri | F44: Depilación bikini | G44: Credomatic | H44: 264.5
B45: 45862 | C45: 1577667912 | D45: 1 | E45: Marilu Pierri | F45: Depilación axila | G45: Credomatic | H45: 264.5
B46: 45868 | C46: 3773121931 | D46: 4 | E46: Kristell Rocio Olivares Lopez | F46: Depilación axila | G46: Visa | H46: 600
B47: 45868 | C47: 3773121931 | D47: 4 | E47: Kristell Rocio Olivares Lopez | F47: Depilación piernas | G47: Visa | H47: 1100
B48: 45868 | C48: 3773121931 | D48: 4 | E48: Kristell Rocio Olivares Lopez | F48: Depilación bikini | G48: Visa | H48: 900
B49: 45876 | C49: 1661225929 | D49: 4 | E49: Valentina Escobar | F49: Depilación bikini | G49: Visa | H49: 925
B50: 45876 | C50: 1661225929 | D50: 4 | E50: Valentina Escobar | F50: Depilación axila | G50: Visa | H50: 700
B51: 45876 | C51: 1661225929 | D51: 4 | E51: Valentina Escobar | F51: Depilación piernas completa | G51: Visa | H51: 1250
... B96: 46010 | C96: 3258402429 | D96: 1 | E96: Rebeca Juarez | F96: Depilación axila | G96: Credomatic | H96: 250
E97: Total | H97: =SUM(H3:H96) -> 74362.5

Sheet Emsculpt
A1: Emsculpt | B1: Fecha | C1: No. de Factura | D1: Cantidad | E1: Nombre del Paciente | F1: Tratamiento | G1: Forma de Pago | H1: Total
B3: 45756 | C3: 2193049518 | D3: 5 | E3: Ana Rebeca Higueros Del Carro | F3: Emsculpt biceps | G3: Visa L. | H3: 7500
B4: 45825 | C4: 3703128810 | D4: 6 | E4: Guillermo Mendoza | F4: Emsculpt brazos | G4: Visa | H4: 7500
E5: Total | H5: =SUM(H3:H4) -> 15000

Sheet Emtone
A1: Emtone | B1: Fecha | C1: No. de Factura | D1: Cantidad | E1: Nombre del Paciente | F1: Tratamiento | G1: Forma de Pago | H1: Total
B3: 45664 | C3: 1532448300 | D3: 8 | E3: Gabriela Cuellar | F3: Emtone abdomen y espalda baja | G3: Visa | H3: 5000
B4: 45670 | C4: 3038333533 | D4: 8 | E4: Ana Longo De Arias | F4: Emtone abdomen, cintura y espalda baja | G4: Visa | H4: 5000
B5: 45670 | C5: 3034926286 | D5: 8 | E5: Maria De Los Angeles Paz | F5: Emtone medias piernas completas | G5: Visa | H5: 5000
B6: 45672 | C6: 3368960788 | D6: 8 | E6: Ana Raquel Rios | F6: Emtone abdomen, cintura y piernas | G6: Visa | H6: 5000
B7: 45694 | C7: 255937579 | D7: 8 | E7: Debora Cividanis De Garrido | F7: Emtone abdomen, cintura, brazos, chaparrera, entrepierna y parte posterior de la pierna | G7: Visa | H7: 5000
B8: 45698 | C8: 2736081297 | D8: 8 | E8: Surisaddai Garcia | F8: Emtone abdomen, cintura, brazos y parte posterior de la pierna | G8: Visa | H8: 5000
B9: 45712 | C9: 2157464973 | D9: 2 | E9: Carmen Liliana Rivera | F9: Emtone brazos | G9: Credomatic | H9: 1250
B10: 45720 | C10: 686968060 | D10: 8 | E10: Ana Rebeca Higueros del Carro | F10: Emtone corporal | G10: Visa L. | H10: 5000
B11: 45756 | C11: 415777700 | D11: 8 | E11: Gloria Carrion | F11: Emtone medias chaparreras, entrepierna y parte posterior | G11: Visa | H11: 5000
B12: 45806 | C12: 1539461016 | D12: 8 | E12: Debora Sinibaldi De Garrido | F12: Emtone corporal | G12: Visa L. | H12: 5000
B13: 45814 | C13: 455099357 | D13: 8 | E13: Patricia Lemus | F13: Emtone corporal | G13: Deposito | H13: 5000
B14: 45817 | C14: 3841346753 | D14: 8 | E14: Maria Fernanda Chavez | F14: Emtone medias piernas completas | G14: Visa | H14: 5000
... B26: 46008 | C26: 1005801119 | D26: 8 | E26: Astrid Daniela Fischer Zablah | F26: Emtone corporal | G26: Deposito | H26: 5000
E27: Total | H27: =SUM(H3:H26) -> 115000

Sheet Exilis
A1: Exilis | B1: Fecha | C1: No. de Factura | D1: Cantidad | E1: Nombre del Paciente | F1: Tratamiento | G1: Forma de Pago | H1: Total
B3: 45670 | C3: 3038333533 | D3: 8 | E3: Ana Longo De Arias | F3: Exilis abdomen, cintura y espalda completa | G3: Visa | H3: 6500
B4: 45679 | C4: 142886173 | D4: 8 | E4: Edwin Solares | F4: Exilis abdomen, cintura y espalda baja | G4: Visa | H4: 6500
B5: 45684 | C5: 3837280768 | D5: 8 | E5: Miriam Vanessa Castillo | F5: Exilis abdomen, cintura, espalda y brazos | G5: Visa | H5: 6500
B6: 45691 | C6: 421675310 | D6: 4 | E6: Astrid De Leon | F6: Exilis cuello | G6: Visa | H6: 1600
B7: 45693 | C7: 964837510 | D7: 8 | E7: Betania Goncalves | F7: Exilis glúteos | G7: Visa | H7: 6500
B8: 45694 | C8: 1228620836 | D8: 4 | E8: Myriam Mijangos De Weller | F8: Exilis abodmen y cintura | G8: Visa | H8: 3250
B9: 45694 | C9: 1228620836 | D9: 4 | E9: Ricardo Weller | F9: Exilis corporal | G9: Visa | H9: 3250
B10: 45698 | C10: 2736081297 | D10: 8 | E10: Ricardo Moreno | F10: Exilis abdomen, cintura, pectoral, aletas y espalda baja | G10: Visa | H10: 6500
B11: 45698 | C11: 2736081297 | D11: 8 | E11: Surisaddai Garcia | F11: Exilis abdomen, cintura, espalda alta, brazos y parte posterior de la pierna | G11: Visa | H11: 6500
B12: 45707 | C12: 544360517 | D12: 5 | E12: Mayde Sanabria de Moscoso | F12: Exilis rostro y cuello | G12: Visa | H12: 3165
B13: 45707 | C13: 544360517 | D13: 1 | E13: Mayde Sanabria de Moscoso | F13: Exilis rostro y cuello | G13: Visa | H13: 635
B14: 45715 | C14: 1361987954 | D14: 4 | E14: Ninoshtka Vargas | F14: Abono exilis abdomen, cintura, espalda y brazos | G14: Credomatic | H14: 3500
... B77: 46022 | C77: 3451997700 | D77: 1 | E77: Marisa Celasco | F77: Abono exilis corporal | G77: Visa L. | H77: 5000
E78: Total | H78: =SUM(H3:H77) -> 352825.01

Sheet Exfoliación
A1: Exfoliación | B1: Fecha | C1: No. de Factura | D1: Cantidad | E1: Nombre del Paciente | F1: Tratamiento | G1: Forma de Pago | H1: Total
B3: 45771 | C3: 3667872970 | D3: 1 | E3: Ninoshtka Vargas | F3: Exfoliación corporal | G3: Credomatic | H3: 350
B4: 45772 | C4: 778718326 | D4: 1 | E4: Velkis Santos | F4: Exfoliación corporal | G4: Credomatic | H4: 350
B5: 45789 | C5: 1534545575 | D5: 1 | E5: Cesibel Alejos | F5: Exfoliación corporal | G5: Visa | H5: 200
B6: 45828 | C6: 3037152131 | D6: 1 | E6: Bonna Marroquin | F6: Exfoliación corporal | G6: Credomatic | H6: 350
E7: Total | H7: =SUM(H3:H6) -> 1250

Sheet Facial purificante
A1: Facial purificante | B1: Fecha | C1: No. de Factura | D1: Cantidad | E1: Nombre del Paciente | F1: Tratamiento | G1: Forma de Pago | H1: Total
B3: 45681 | C3: 2411089083 | D3: 1 | E3: Bessy Chan | F3: Facial purificante | G3: Credomatic | H3: 402.5
B4: 45688 | C4: 1813269753 | D4: 1 | E4: Alvaro Florido | F4: Facial purificante | G4: Credomatic | H4: 575
B5: 45691 | C5: 3459662054 | D5: 1 | E5: Libni Hernandez | F5: Facial purificante | G5: Credomatic | H5: 575
B6: 45691 | C6: 129846122 | D6: 1 | E6: Rita Castillo | F6: Facial purificante | G6: Visa L. | H6: 575
B7: 45692 | C7: 2071153019 | D7: 1 | E7: Aida Lopez | F7: Facial purificante | G7: Credomatic | H7: 575
B8: 45693 | C8: 265765863 | D8: 1 | E8: Marcos Aquino | F8: Facial purificante | G8: Credomatic | H8: 575
B9: 45699 | C9: 2956214625 | D9: 1 | E9: Isabela Gabriel Castillo | F9: Facial purificante | G9: Visa | H9: 575
B10: 45701 | C10: 2024884464 | D10: 1 | E10: Elien Escobar | F10: Facial purificante | G10: Credomatic | H10: 575
B11: 45705 | C11: 3947122234 | D11: 1 | E11: Claudia Soch | F11: Facial purificante | G11: Visa L. | H11: 575
B12: 45709 | C12: 1027034747 | D12: 1 | E12: Ana Maria Martinez | F12: Facial purificante | G12: Credomatic | H12: 400
B13: 45719 | C13: 3678815013 | D13: 3 | E13: Maziel Arango | F13: Facial purificante | G13: Credomatic | H13: 1119
B14: 45721 | C14: 3428600099 | D14: 1 | E14: Ana Gabriela Linares | F14: Facial purificante | G14: Visa | H14: 575
... B57: 46007 | C57: 3254863596 | D57: 1 | E57: Gabriela Ambrocio | F57: Facial purificante | G57: Credomatic | H57: 575
E58: Total | H58: =SUM(H3:H57) -> 38735.5

Sheet Hifu
A1: Hifu | B1: Fecha | C1: No. de Factura | D1: Cantidad | E1: Nombre del Paciente | F1: Tratamiento | G1: Forma de Pago | H1: Total
B3: --- | C3: --- | D3: --- | E3: --- | F3: --- | G3: --- | H3: 0
E4: Total | H4: =SUM(H3:H3) -> 0

Sheet Hydrafacial
A1: Hydrafacial | B1: Fecha | C1: No. de Factura | D1: Cantidad | E1: Nombre del Paciente | F1: Tratamiento | G1: Forma de Pago | H1: Total
B3: 45681 | C3: 2742634699 | D3: 1 | E3: Alisson Batres | F3: Hydrafacial | G3: Credomatic | H3: 650
B4: 45681 | C4: 3033219464 | D4: 1 | E4: Jaqueline Barillas | F4: Hydrafacial | G4: Visa L. | H4: 650
B5: 45684 | C5: 2389197170 | D5: 4 | E5: Arturo Salvatierra | F5: Hydrafacial | G5: Visa | H5: 2250
B6: 45684 | C6: 2389197170 | D6: 4 | E6: Mariela Saravia | F6: Hydrafacial | G6: Visa | H6: 2250
B7: 45698 | C7: 1166950413 | D7: 1 | E7: Reishell Barillas | F7: Hydrafacial | G7: Deposito | H7: 650
B8: 45716 | C8: 1736196845 | D8: 1 | E8: Ileana De Carrera | F8: Hydrafacial | G8: Visa | H8: 834
B9: 45721 | C9: 3428600099 | D9: 1 | E9: Ana Gabriela Linares | F9: Hydrafacial | G9: Visa | H9: 834
B10: 45726 | C10: 96554752 | D10: 2 | E10: Ivonne Rodas De Gonzalez | F10: Hydrafacial | G10: Visa | H10: 1100
B11: 45748 | C11: 3571860187 | D11: 1 | E11: Ana Lucia Conde | F11: Hydrafacial | G11: Credomatic | H11: 834
B12: 45750 | C12: 1559382418 | D12: 1 | E12: Julianne Cummings | F12: Hydrafacial | G12: Visa | H12: 650
B13: 45758 | C13: 2297907006 | D13: 2 | E13: Bessy Chan | F13: Hydrafacial | G13: Visa L. | H13: 1668
B14: 45768 | C14: 1752058383 | D14: 1 | E14: Valeria Meany | F14: Hydrafacial | G14: Credomatic | H14: 834
... B51: 46006 | C51: 2591705163 | D51: 2 | E51: Julianne Cummings | F51: Hydrafacial | G51: Credomatic | H51: 1334
E52: Total | H52: =SUM(H3:H51) -> 56749.379

Sheet Laboratorios
A1: Laboratorios | B1: Fecha | C1: No. de Factura | D1: Cantidad | E1: Nombre del Paciente | F1: Tratamiento | G1: Forma de Pago | H1: Total
B3: 45947 | C3: 4241509226 | D3: 1 | E3: Mayra Vasquez Alvarado | F3: Laboratorios pre-celulas | G3: Deposito | H3: 950
B4: 45965 | C4: 3854256230 | D4: 1 | E4: Ruth Sazo | F4: Laboratorios pre-celulas | G4: Visa L. | H4: 950
E5: Total | H5: =SUM(H3:H4) -> 1900

Sheet Masaje linfatico
A1: Masaje linfatico | B1: Fecha | C1: No. de Factura | D1: Cantidad | E1: Nombre del Paciente | F1: Tratamiento | G1: Forma de Pago | H1: Total
B3: 45664 | C3: 220520352 | D3: 1 | E3: Alejandra Quinto | F3: Masaje linfatico | G3: Credomatic | H3: 200
B4: 45672 | C4: 45565309 | D4: 2 | E4: Francisco Manzo | F4: Masaje linfatico facial | G4: Visa | H4: 300
B5: 45691 | C5: 421675310 | D5: 4 | E5: Astrid De Leon | F5: Masaje linfatico | G5: Visa | H5: 800
B6: 45747 | C6: 333070738 | D6: 5 | E6: Dessire Oaxaca | F6: Masaje linfatico | G6: Visa | H6: 1000
B7: 45747 | C7: 333070738 | D7: 5 | E7: Ethia Hurtado | F7: Masaje linfatico | G7: Credomatic | H7: 1000
B8: 45748 | C8: 1214269070 | D8: 2 | E8: Alejandra Quinto | F8: Masaje linfatico | G8: Efectivo | H8: 400
B9: 45755 | C9: 312623192 | D9: 4 | E9: Astrid Ordoñez | F9: Masaje linfatico | G9: Credomatic | H9: 800
B10: 45756 | C10: 415777700 | D10: 8 | E10: Gloria Carrion | F10: Masaje linfatico | G10: Visa | H10: 2000
B11: 45758 | C11: 102387171 | D11: 1 | E11: Alejandra Quinto | F11: Masaje linfatico | G11: Efectivo | H11: 200
B12: 45796 | C12: 2963359813 | D12: 10 | E12: Nancy Mendoza | F12: Masaje linfatico | G12: Credomatic | H12: 2000
B13: 45800 | C13: 1507804806 | D13: 10 | E13: Claudia Romero | F13: Masaje linfatico | G13: Visa | H13: 2000
B14: 45806 | C14: 273435800 | D14: 5 | E14: Leslie Chilin | F14: Masaje linfatico | G14: Efectivo | H14: 1000
... B31: 45994 | C31: 1847479170 | D31: 5 | E31: Carolina Castillo | F31: Masaje linfatico | G31: Credomatic | H31: 1000
E32: Total | H32: =SUM(H3:H31) -> 31550

Sheet Mesoterapia
A1: Mesoterapia | B1: Fecha | C1: No. de Factura | D1: Cantidad | E1: Nombre del Paciente | F1: Tratamiento | G1: Forma de Pago | H1: Total
B3: 45694 | C3: 1228620836 | D3: 2 | E3: Myriam Mijangos De Weller | F3: Mesoterapia abdomen y cintura | G3: Visa | H3: 2856
B4: 45694 | C4: 1228620836 | D4: 2 | E4: Myriam Mijangos De Weller | F4: Mesoterapia chaparreras | G4: Visa | H4: 2856
B5: 45694 | C5: 1228620836 | D5: 4 | E5: Myriam Mijangos De Weller | F5: Mesoterapia brazos y espalda | G5: Visa | H5: 1500
B6: 45701 | C6: 2853981145 | D6: 2 | E6: Mariana Hernandez | F6: Mesoterpia reductora abdomen y cintura | G6: Deposito | H6: 1200
B7: 45701 | C7: 2853981145 | D7: 1 | E7: Mariana Hernandez | F7: Abono mesoterapia reductora abdomen y cintura | G7: Deposito | H7: 400
B8: 45706 | C8: 253903913 | D8: 10 | E8: Fracisco Arce | F8: Mesoterapia reductora y reafirmante abdomen, cintura y espalda baja | G8: Visa L. | H8: 7500
B9: 45712 | C9: 2786017757 | D9: 2 | E9: Mariana Hernandez | F9: Mesoterpia reductora abdomen y cintura | G9: Deposito | H9: 1200
B10: 45712 | C10: 2786017757 | D10: 1 | E10: Mariana Hernandez | F10: Abono mesoterapia reductora abdomen y cintura | G10: Deposito | H10: 400
B11: 45720 | C11: 686968060 | D11: 8 | E11: Ana Rebeca Higueros del Carro | F11: Mesoterapia | G11: Visa L. | H11: 4000
B12: 45727 | C12: 3245099025 | D12: 8 | E12: Ana Rebeca Higueros del Carro | F12: Mesoterapia vitamina C gluteos | G12: Credomatic | H12: 3200
B13: 45729 | C13: 1462453453 | D13: 10 | E13: Carla De Zelaya | F13: Mesoterapia reductora abdomen y cintura | G13: Credomatic | H13: 5000
B14: 45729 | C14: 3055373476 | D14: 1 | E14: Mariana Hernandez | F14: Cancelación mesoterapia reductora abdomen y cintura | G14: Deposito | H14: 200
... B44: 45975 | C44: 3248966351 | D44: 10 | E44: Mildred Roxana Barrientos | F44: Mesoterapia corporal | G44: Visa | H44: 4950
E45: Total | H45: =SUM(H3:H44) -> 111627

Sheet Morpheus
A1: Morpheus | B1: Fecha | C1: No. de Factura | D1: Cantidad | E1: Nombre del Paciente | F1: Tratamiento | G1: Forma de Pago | H1: Total
B3: 45670 | C3: 3038333533 | D3: 2 | E3: Ana Longo De Arias | F3: Morpheus rostro y cuello | G3: Visa | H3: 10000
B4: 45671 | C4: 1109345378 | D4: 2 | E4: Silvia Canella | F4: Morpheus rostro y cuello | G4: Credomatic | H4: 10000
B5: 45672 | C5: 3368960788 | D5: 2 | E5: Ana Raquel Rios | F5: Morpheus rostro y cuello | G5: Visa | H5: 10000
B6: 45673 | C6: 2309900924 | D6: 2 | E6: Berenice Urzua | F6: Morpheus rostro y cuello | G6: Visa | H6: 10000
B7: 45677 | C7: 3576581540 | D7: 2 | E7: Vinicio Suchini | F7: Morpheus rostro y cuello | G7: Visa | H7: 10000
B8: 45678 | C8: 3438365580 | D8: 2 | E8: Ilse Eckstein | F8: Morpheus rostro y cuello | G8: Credomatic | H8: 10000
B9: 45679 | C9: 2776255686 | D9: 2 | E9: Rocio Molina | F9: Morpheus rostro y cuello | G9: Visa L. | H9: 10000
B10: 45679 | C10: 1233602801 | D10: 2 | E10: Vanessa Smith De Vargas | F10: Morpheus rostro y cuello | G10: Visa L. | H10: 10000
B11: 45680 | C11: 858016581 | D11: 2 | E11: Tere De Bolaños | F11: Morpheus corporal | G11: Visa L. | H11: 10000
B12: 45684 | C12: 356533895 | D12: 2 | E12: Rosa Maria Miralles | F12: Morpheus rostro y cuello | G12: Credomatic | H12: 10000
B13: 45684 | C13: 187779292 | D13: 2 | E13: Wendy Gonzalez | F13: Morpheus rostro y cuello | G13: Credomatic | H13: 10000
B14: 45686 | C14: 3701163459 | D14: 2 | E14: Claudia Arrecis | F14: Morpheus rostro y cuello | G14: Efectivo | H14: 10000
... B126: 46022 | C126: 1424903467 | D126: 2 | E126: Diana Velasquez | F126: Morpheus rostro y cuello | G126: Visa L. | H126: 10000
E127: Total | H127: =SUM(H3:H126) -> 1268200

Sheet Pico-láser
A1: Pico-láser | B1: Fecha | C1: No. de Factura | D1: Cantidad | E1: Nombre del Paciente | F1: Tratamiento | G1: Forma de Pago | H1: Total
B3: --- | C3: --- | D3: --- | E3: --- | F3: --- | G3: --- | H3: ---
E4: Total | H4: =SUM(H3:H3) -> 0

Sheet Profhilo
A1: Porfhilo | B1: Fecha | C1: No. de Factura | D1: Cantidad | E1: Nombre del Paciente | F1: Tratamiento | G1: Forma de Pago | H1: Total
B3: 45671 | C3: 814566760 | D3: 1 | E3: Julia Sapper | F3: Aplicación de profhilo | G3: Visa | H3: 2500
B4: 45673 | C4: 2309900924 | D4: 2 | E4: Berenice Urzua | F4: Aplicación de profhilo | G4: Visa | H4: 5000
B5: 45677 | C5: 1770408293 | D5: 1 | E5: Kristalh Fuentes | F5: Aplicación de profhilo | G5: Deposito | H5: 2500
B6: 45677 | C6: 3576581540 | D6: 2 | E6: Vinicio Suchini | F6: Aplicación de profhilo | G6: Visa | H6: 5000
B7: 45678 | C7: 3438365580 | D7: 2 | E7: Ilse Eckstein | F7: Aplicación de profhilo | G7: Credomatic | H7: 5000
B8: 45679 | C8: 1484147248 | D8: 2 | E8: Ana Isabel Figueroa | F8: Aplicación de profhilo | G8: Visa | H8: 5000
B9: 45684 | C9: 356533895 | D9: 2 | E9: Rosa Maria Miralles | F9: Aplicación de profhilo | G9: Credomatic | H9: 5000
B10: 45684 | C10: 1492928895 | D10: 1 | E10: Julia Sapper | F10: Abono aplicación de profhilo | G10: Credomatic | H10: 1500
B11: 45686 | C11: 3701163459 | D11: 2 | E11: Claudia Arrecis | F11: Aplicación de profhilo | G11: Efectivo | H11: 5000
B12: 45687 | C12: 1917733017 | D12: 2 | E12: Zoila Valencia Marroquin | F12: Aplicación de profhilo | G12: Credomatic | H12: 5000
B13: 45687 | C13: 1917733017 | D13: 2 | E13: Ramon Canek | F13: Aplicación de profhilo | G13: Credomatic | H13: 5000
B14: 45691 | C14: 4110697988 | D14: 2 | E14: Antonella Ricci | F14: Aplicación de profhilo | G14: Visa | H14: 5000
... B78: 46022 | C78: 194070282 | D78: 2 | E78: Mariela Saravia | F78: Aplicación de profhilo rostro | G78: Visa L. | H78: 5000
E79: Total | H79: =SUM(H3:H78) -> 331150

Sheet PRP
A1: PRP | B1: Fecha | C1: No. de Factura | D1: Cantidad | E1: Nombre del Paciente | F1: Tratamiento | G1: Forma de Pago | H1: Total
B3: 45671 | C3: 1689274031 | D3: 1 | E3: Yaneth De Velez | F3: PRP rostro y cuello | G3: Visa | H3: 1200
B4: 45672 | C4: 104678237 | D4: 3 | E4: Emma De Leon | F4: PRP rostro y cuello | G4: Credomatic | H4: 3600
B5: 45674 | C5: 3614983127 | D5: 2 | E5: Carolina Ibarra | F5: PRP rostro y cuello | G5: Visa | H5: 2532
B6: 45674 | C6: 3614983127 | D6: 1 | E6: Carolina Ibarra | F6: PRP rostro y cuello | G6: Visa | H6: 1268
B7: 45680 | C7: 2928297753 | D7: 3 | E7: Ana Riera De Orellana | F7: PRP rostro y cuello | G7: Visa | H7: 3888
B8: 45684 | C8: 1398754801 | D8: 1 | E8: Gisela Castillo | F8: PRP rostro | G8: Cheque | H8: 800
B9: 45686 | C9: 2331922080 | D9: 1 | E9: Marcela Barquin | F9: PRP rostro y cuello | G9: Credomatic | H9: 1600
B10: 45692 | C10: 3982314618 | D10: 3 | E10: Samira Massis | F10: PRP rostro y cuello | G10: Visa L. | H10: 3600
B11: 45698 | C11: 3090433388 | D11: 10 | E11: Virginia Castillo | F11: PRP rostro y cuello | G11: Credomatic | H11: 12000
B12: 45701 | C12: 3569110488 | D12: 1 | E12: Ruth Sazo | F12: PRP escote | G12: Visa | H12: 1000
B13: 45701 | C13: 3569110488 | D13: 1 | E13: Ruth Sazo | F13: PRP manos | G13: Visa | H13: 1000
B14: 45701 | C14: 3569110488 | D14: 1 | E14: Ruth Sazo | F14: PRP rodillas | G14: Visa | H14: 1000
... B124: 45993 | C124: 740574739 | D124: 1 | E124: Ruth Sazo | F124: PRP antebrazo | G124: Visa | H124: 1565
E125: Total | H125: =SUM(H3:H124) -> 289752.99

Sheet Radiofrecuencia
A1: Radiofrecuencia | B1: Fecha | C1: No. de Factura | D1: Cantidad | E1: Nombre del Paciente | F1: Tratamiento | G1: Forma de Pago | H1: Total
B3: 45671 | C3: 507790994 | D3: 6 | E3: Edgar Muñoz | F3: Radiofrecuecia rosro y cuello | G3: Visa | H3: 3000
B4: 45677 | C4: 3576581540 | D4: 6 | E4: Sol Lopez | F4: Radiofrecuecia rosro y cuello | G4: Visa | H4: 3204
B5: 45693 | C5: 964837510 | D5: 5 | E5: Betania Goncalves | F5: Radiofrecuencia abdomen, cintura y espalda | G5: Visa | H5: 2915
B6: 45693 | C6: 964837510 | D6: 1 | E6: Betania Goncalves | F6: Radiofrecuencia abdomen, cintura y espalda | G6: Visa | H6: 585
B7: 45694 | C7: 1757168799 | D7: 6 | E7: Ivone Martinez | F7: Radiofrecuencia rostro y cuello | G7: Visa | H7: 2670
B8: 45705 | C8: 2406892366 | D8: 5 | E8: Maria Fernanda Martinez | F8: Radiofrecuencia rostro y cuello | G8: Credomatic | H8: 2915
B9: 45705 | C9: 2406892366 | D9: 1 | E9: Maria Fernanda Martinez | F9: Radiofrecuencia rostro y cuello | G9: Credomatic | H9: 585
B10: 45716 | C10: 3580642323 | D10: 6 | E10: Jorge Daniel Cifuentes | F10: Radiofrecuencia abdomen completo, cintura y espalda baja | G10: Visa | H10: 5358
B11: 45719 | C11: 2057388271 | D11: 2 | E11: Gloria Ralda | F11: Radiofrecuencia rostro y cuello | G11: Visa L. | H11: 700
B12: 45721 | C12: 3065268884 | D12: 6 | E12: Francisco Arce | F12: Radiofrecuencia rostro y cuello | G12: Visa L. | H12: 3000
B13: 45727 | C13: 3540928000 | D13: 3 | E13: Fabiola Xep | F13: Radiofrecuencia abdomen, cintura, espalda alta y brazos | G13: Visa L. | H13: 1500
B14: 45750 | C14: 1125401592 | D14: 6 | E14: Olga De Sosa | F14: Radiofrecuencia rostro, cuello y escote | G14: Visa L. | H14: 3000
... B47: 46010 | C47: 2560379794 | D47: 6 | E47: Rebeca Juarez | F47: Radiofrecuencia rostro y cuello | G47: Credomatic | H47: 3471
E48: Total | H48: =SUM(H3:H47) -> 126038

Sheet Ultrasonido
A1: Ultrasonido post-operatorio | B1: Fecha | C1: No. de Factura | D1: Cantidad | E1: Nombre del Paciente | F1: Tratamiento | G1: Forma de Pago | H1: Total
B3: 45677 | C3: 1116554040 | D3: 5 | E3: Arturo Salvatierra | F3: Ultrasonido post-operatorio | G3: Visa | H3: 900
B4: 45701 | C4: 2066762206 | D4: 2 | E4: Arturo Salvatierra | F4: Ultrasonido post-operatorio | G4: Visa L. | H4: 360
B5: 45712 | C5: 855392754 | D5: 1 | E5: Juan Jose Mata | F5: Ultrasonido post-operatorio | G5: Efectivo | H5: 200
B6: 45713 | C6: 3055635653 | D6: 1 | E6: Juan Jose Mata | F6: Ultrasonido post-operatorio | G6: Efectivo | H6: 200
B7: 45714 | C7: 3716304336 | D7: 1 | E7: Juan Jose Mata | F7: Ultrasonido post-operatorio | G7: Efectivo | H7: 200
B8: 45755 | C8: 312623192 | D8: 4 | E8: Astrid Ordoñez | F8: Ultrasonido post-operatorio | G8: Credomatic | H8: 800
B9: 45756 | C9: 3717811064 | D9: 6 | E9: Pilar Iglesias | F9: Ultrasonido post-operatorio | G9: Visa L. | H9: 1200
B10: 45826 | C10: 4149824284 | D10: 5 | E10: Helen Escaler | F10: Ultrasonido post-operatorio | G10: Visa | H10: 1000
B11: 45852 | C11: 1532973000 | D11: 6 | E11: Karla Sarti De Bonatti | F11: Ultrasonido post-operatorio | G11: Credomatic | H11: 1080
B12: 45852 | C12: 542786875 | D12: 5 | E12: Jose Eduardo Rivera | F12: Ultrasonido post-operatorio | G12: Visa | H12: 1000
B13: 45881 | C13: 1834369444 | D13: 10 | E13: Silvana Giono de Suger | F13: Ultrasonido post-operatorio | G13: Credomatic | H13: 2000
B14: 45881 | C14: 1149518204 | D14: 5 | E14: Astrid Ramirez Pinto | F14: Ultrasonido post-operatorio | G14: Visa | H14: 1000
... B22: 46010 | C22: 4063840383 | D22: 4 | E22: Miriam Del Rosario Bolaños | F22: Ultrasonido post-operatorio | G22: Credomatic | H22: 800
E23: Total | H23: =SUM(H3:H22) -> 19800

Sheet Velo de acido hialuronico
A1: Velo de acido hialuronico | B1: Fecha | C1: No. de Factura | D1: Cantidad | E1: Nombre del Paciente | F1: Tratamiento | G1: Forma de Pago | H1: Total
B3: --- | C3: --- | D3: --- | E3: --- | F3: --- | G3: --- | H3: 0
E4: Total | H4: =SUM(H3:H3) -> 0

Sheet Velox
A1: Velox | B1: Fecha | C1: No. de Factura | D1: Cantidad | E1: Nombre del Paciente | F1: Tratamiento | G1: Forma de Pago | H1: Total
B3: --- | C3: --- | D3: --- | E3: --- | F3: --- | G3: --- | H3: 0
E4: Total | H4: =SUM(H3:H3) -> 0

Sheet Vitamina C intravenosa
A1: Vitamina C intravenosa | B1: Fecha | C1: No. de Factura | D1: Cantidad | E1: Nombre del Paciente | F1: Tratamiento | G1: Forma de Pago | H1: Total
B3: 45663 | C3: 3837808205 | D3: 1 | E3: Lissete Cifuentes | F3: Aplicación de vitamina C intravenosa | G3: Visa L. | H3: 500
B4: 45663 | C4: 823017476 | D4: 3 | E4: Jossleine Rodriguez | F4: Aplicación de vitamina C intravenosa | G4: Visa L. | H4: 1605
B5: 45673 | C5: 1633439171 | D5: 1 | E5: Mary Contreras | F5: Aplicación de vitamina C intravenosa | G5: Credomatic | H5: 535
B6: 45673 | C6: 3707455606 | D6: 3 | E6: Telma Maldonado | F6: Aplicación de vitamina C intravenosa | G6: Efectivo | H6: 1605
B7: 45673 | C7: 3707455606 | D7: 1 | E7: Telma Maldonado | F7: Abono Dabalash | G7: Efectivo | H7: 370
B8: 45678 | C8: 3438365580 | D8: 1 | E8: Ilse Eckstein | F8: Aplicación de vitamina C intravenosa | G8: Credomatic | H8: 535
B9: 45679 | C9: 1126647214 | D9: 1 | E9: Carlos Arnoldo Rodriguez | F9: Aplicación de vitamina C intravenosa | G9: Credomatic | H9: 535
B10: 45679 | C10: 1377846786 | D10: 1 | E10: Glenda Lopez | F10: Aplicación de vitamina C intravenosa | G10: Efectivo | H10: 535
B11: 45684 | C11: 1398754801 | D11: 1 | E11: Gisela Castillo | F11: Aplicación de vitamina C intravenosa | G11: Cheque | H11: 376
B12: 45687 | C12: 2001814206 | D12: 1 | E12: Wendy Lopez | F12: Aplicación de vitamina C intravenosa | G12: Credomatic | H12: 535
B13: 45693 | C13: 477317611 | D13: 1 | E13: Gabriela Saenz | F13: Aplicación de vitamina C intravenosa | G13: Credomatic | H13: 535
B14: 45693 | C14: 2090221636 | D14: 1 | E14: Francis Cuellar | F14: Aplicación de vitamina C intravenosa | G14: Credomatic | H14: 535
... B138: 46008 | C138: 1005801119 | D138: 3 | E138: Astrid Daniela Fischer Zablah | F138: Aplicación de vitamina C intravenosa | G138: Deposito | H138: 1605
E139: Total | H139: =SUM(H3:H138) -> 144479.48

Sheet Ciclo coolsculpting
A1: Ciclo coolsculpting | B1: Fecha | C1: No. de Factura | D1: Cantidad | E1: Nombre del Paciente | F1: Tratamiento | G1: Forma de Pago | H1: Total
B3: 45776 | C3: 2526954006 | D3: 2 | E3: Celso Cerezo | F3: Ciclos coolsculpting | G3: Visa L. | H3: 9000
B4: 45776 | C4: 1964985645 | D4: 2 | E4: Zully Rodriguez De Cerezo | F4: Ciclos coolsculpting | G4: Visa L. | H4: 9000
E5: Total | H5: =SUM(H3:H4) -> 18000

Sheet Dermapen
A1: Dermapen | B1: Fecha | C1: No. de Factura | D1: Cantidad | E1: Nombre del Paciente | F1: Tratamiento | G1: Forma de Pago | H1: Total
B3: 45701 | C3: 341655587 | D3: 1 | E3: Silvia Cabrera De Rivera | F3: Dermapen rostro y cuello | G3: Credomatic | H3: 1300
B4: 45813 | C4: 885278313 | D4: 1 | E4: Silvia De Rivera | F4: Dermapen rostro y cuello | G4: Credomatic | H4: 1200
B5: 45820 | C5: 2583184228 | D5: 1 | E5: Alexa Caballero | F5: Dermapen rostro y cuello | G5: Deposito | H5: 1800
B6: 45883 | C6: 2960475740 | D6: 2 | E6: Silvia Cabrera De Rivera | F6: Dermapen rostro y cuello ADN de salmon | G6: Visa | H6: 2866
B7: 45883 | C7: 2960475740 | D7: 1 | E7: Silvia Cabrera De Rivera | F7: Dermapen rostro y cuello ADN de salmon | G7: Visa | H7: 1434
B8: 45889 | C8: 781467669 | D8: 2 | E8: Alejandro Castellanos Castillo | F8: Dermapen rostro y cuello ADN de salmon | G8: Visa | H8: 2860
B9: 45889 | C9: 781467669 | D9: 1 | E9: Alejandro Castellanos Castillo | F9: Dermapen rostro y cuello ADN de salmon | G9: Visa | H9: 1440
B10: 45903 | C10: 3880732992 | D10: 3 | E10: Vanessa Smtih De Vargas | F10: Dermapen rostro y cuello ADN de Salmon | G10: Visa L. | H10: 3900
B11: 45918 | C11: 2908045371 | D11: 3 | E11: Maria Jose Solares | F11: Dermapen rostro y cuello ADN de Salmon | G11: Visa L. | H11: 3300
B12: 45937 | C12: 1445351269 | D12: 2 | E12: Gissell Sanzogni | F12: Dermapen rostro y cuello ADN de salmon | G12: Visa L. | H12: 2800
B13: 45937 | C13: 1445351269 | D13: 1 | E13: Gissell Sanzogni | F13: Dermapen rostro y cuello ADN de salmon | G13: Visa L. | H13: 1500
B14: 45960 | C14: 2980398406 | D14: 3 | E14: Melissa Pineda | F14: Dermapen rostro y cuello ADN de salmon | G14: Visa | H14: 3000
... B22: 46001 | C22: 2237613416 | D22: 1 | E22: Regina Molina | F22: Dermapen rostro y cuello ADN de salmon | G22: Credomatic | H22: 2000
E23: Total | H23: =SUM(H3:H22) -> 46000

Sheet Láser CO2
A1: Láser CO2 | B1: Fecha | C1: No. de Factura | D1: Cantidad | E1: Nombre del Paciente | F1: Tratamiento | G1: Forma de Pago | H1: Total
B3: 45800 | C3: 343689690 | D3: 1 | E3: Mary Contreras | F3: Laser Co2 | G3: Visa L. | H3: 5000
B4: 45896 | C4: 3272952083 | D4: 1 | E4: Rita Stella Roesch Diaz | F4: Laser CO2 | G4: Visa | H4: 5600
B5: 45973 | C5: 1359890794 | D5: 1 | E5: Gloria Ralda | F5: Lasér CO2 | G5: Deposito | H5: 6000
B6: 45975 | C6: 1173767825 | D6: 1 | E6: Claudia Castillo | F6: Lasér CO2 | G6: Visa L. | H6: 6000
E7: Total | H7: =SUM(H3:H6) -> 22600

Sheet Masaje relajante
A1: Masaje relajante | B1: Fecha | C1: No. de Factura | D1: Cantidad | E1: Nombre del Paciente | F1: Tratamiento | G1: Forma de Pago | H1: Total
B3: 45736 | C3: 615401202 | D3: 1 | E3: Julia Sapper | F3: Masaje corporal exfoliante | G3: Credomatic | H3: 350
B4: 45736 | C4: 2625194223 | D4: 20 | E4: Luis Garrido | F4: Masaje relajante | G4: Visa | H4: 4000
B5: 45737 | C5: 1525698233 | D5: 10 | E5: Jhoana De Leon | F5: Masaje relajante | G5: Efectivo | H5: 2000
B6: 45741 | C6: 1063077935 | D6: 1 | E6: Ruth Noemi Valdez | F6: Masaje corporal exfoliante | G6: Visa | H6: 350
B7: 45789 | C7: 1534545575 | D7: 1 | E7: Cesibel Alejos | F7: Masaje relajante | G7: Visa | H7: 200
B8: 45798 | C8: 4076422012 | D8: 1 | E8: Patrica Chew | F8: Masaje relajante | G8: Credomatic | H8: 250
B9: 45806 | C9: 2935704932 | D9: 10 | E9: Jhoana De Leon | F9: Masaje relajante | G9: Efectivo | H9: 2000
B10: 45852 | C10: 542918507 | D10: 20 | E10: Francisco Arche | F10: Masaje relajante | G10: Visa L. | H10: 4000
B11: 45870 | C11: 777277278 | D11: 10 | E11: Oscar Catu | F11: Masaje relajante | G11: Efectivo | H11: 2000
B12: 45870 | C12: 1709656858 | D12: 10 | E12: Jhoana De Leon | F12: Masaje relajante | G12: Efectivo | H12: 2000
B13: 45918 | C13: 2418033376 | D13: 1 | E13: Gilma Valdez | F13: Masaje relajante | G13: Efectivo | H13: 250
B14: 45943 | C14: 2964275700 | D14: 20 | E14: Luis Garrido | F14: Masaje relajante | G14: Visa | H14: 4000
B15: 45992 | C15: 375933590 | D15: 10 | E15: Zoila Valencia | F15: Masaje relajante | G15: Visa L. | H15: 2000
E16: Total | H16: =SUM(H3:H15) -> 23400

Sheet Oligoelementos
A1: Oligoelementos | B1: Fecha | C1: No. de Factura | D1: Cantidad | E1: Nombre del Paciente | F1: Tratamiento | G1: Forma de Pago | H1: Total
B3: 45929 | C3: 2625326285 | D3: 3 | E3: Myriam Mijangos De Weller | F3: Aplicación de oligoelementos | G3: Visa | H3: 1995
B4: 45958 | C4: 1587758556 | D4: 1 | E4: Monica Mijangos | F4: Aplicación oligoelementos | G4: Credomatic | H4: 700
B5: 45989 | C5: 1864388084 | D5: 3 | E5: Brenda De Hurtado | F5: Aplicación oligoelementos | G5: Deposito | H5: 1395
E6: Total | H6: =SUM(H3:H5) -> 4090

Sheet Grow
A1: Grow | B1: Fecha | C1: No. de Factura | D1: Cantidad | E1: Nombre del Paciente | F1: Tratamiento | G1: Forma de Pago | H1: Total
B3: 45688 | C3: 1699431601 | D3: 1 | E3: Quimica Industrial Guatemalteca, S.A. | F3: Linea telefonica | G3: Cheque | H3: 1461.59
B4: 45688 | C4: 1699431601 | D4: 1 | E4: Quimica Industrial Guatemalteca, S.A. | F4: Servicios prestados recepcionista | G4: Cheque | H4: 3055.5
B5: 45688 | C5: 1699431601 | D5: 1 | E5: Quimica Industrial Guatemalteca, S.A. | F5: Servicios prestados asistente administrativo | G5: Cheque | H5: 3395
B6: 45688 | C6: 1699431601 | D6: 1 | E6: Quimica Industrial Guatemalteca, S.A. | F6: Papeleria y utiles | G6: Cheque | H6: 1200
B7: 45716 | C7: 3308143318 | D7: 1 | E7: Química Industrial Guatemalteca, S.A. | F7: Línea telefonica | G7: Cheque | H7: 1461.59
B8: 45716 | C8: 3308143318 | D8: 1 | E8: Química Industrial Guatemalteca, S.A. | F8: Servicios prestados recepcionista | G8: Cheque | H8: 3055.5
B9: 45716 | C9: 3308143318 | D9: 1 | E9: Química Industrial Guatemalteca, S.A. | F9: Servicios prestados asistente administrativo | G9: Cheque | H9: 3395
B10: 45716 | C10: 3308143318 | D10: 1 | E10: Química Industrial Guatemalteca, S.A. | F10: Por matenimiento | G10: Cheque | H10: 1000
B11: 45747 | C11: 1859994605 | D11: 1 | E11: Química Industrial Guatemalteca, S.A. | F11: Línea telefonica | G11: Cheque | H11: 1461.59
B12: 45747 | C12: 1859994605 | D12: 1 | E12: Química Industrial Guatemalteca, S.A. | F12: Servicios prestados recepcionista | G12: Cheque | H12: 3055.5
B13: 45747 | C13: 1859994605 | D13: 1 | E13: Química Industrial Guatemalteca, S.A. | F13: Servicios prestados asistente administrativo | G13: Cheque | H13: 3395
B14: 45777 | C14: 1746357008 | D14: 1 | E14: Quimica Industrial Guatemalteca, S.A. | F14: Linea telefonica | G14: Cheque | H14: 1461.59
... B42: 46006 | C42: 3218951089 | D42: 1 | E42: Quimica Industrial Guatemalteca, S.A. | F42: Servicios prestados asistente administrativo | G42: Cheque | H42: 3395
E43: Total | H43: =SUM(H3:H42) -> 99645.08

Sheet Abonos a tratamientos
A1: Abono | B1: Fecha | C1: No. de Factura | D1: Cantidad | E1: Nombre del Paciente | F1: Tratamiento | G1: Forma de Pago | H1: Total
B3: 45929 | C3: 463684557 | D3: 1 | E3: Norma De Melville | F3: Abono a tratamiento | G3: Credomatic | H3: 40
B4: 45930 | C4: 389562651 | D4: 1 | E4: Evelyn Sofia Zelaya | F4: Abono a tratamiento | G4: Credomatic | H4: 50
B5: 45978 | C5: 2929608375 | D5: 1 | E5: Cristina Chavez | F5: Abono a tratamiento | G5: Visa L. | H5: 30
E6: Total | H6: =SUM(H3:H5) -> 120

Sheet Celulas madre
A1: Celulas Madre | B1: Fecha | C1: No. de Factura | D1: Cantidad | E1: Nombre del Paciente | F1: Tratamiento | G1: Forma de Pago | H1: Total
B3: 45947 | C3: 4241509226 | D3: 1 | E3: Mayra Vasquez Alvarado | F3: Procedimiento celulas madres | G3: Deposito | H3: 19050
B4: 45965 | C4: 3854256230 | D4: 1 | E4: Ruth Sazo | F4: Procedimiento celulas madres | G4: Visa L. | H4: 19050
E5: Total | H5: =SUM(H3:H4) -> 38100

Sheet Peeling
A1: Peeling | B1: Fecha | C1: No. de Factura | D1: Cantidad | E1: Nombre del Paciente | F1: Tratamiento | G1: Forma de Pago | H1: Total
B3: 45727 | C3: 627262424 | D3: 3 | E3: Reishell Barillas | F3: Peeling despigmentante rostro | G3: Efectivo | H3: 1800
B4: 45818 | C4: 3078900313 | D4: 1 | E4: Maritza Lopez | F4: Abono a peeling despigmentante | G4: Visa | H4: 850
B5: 45820 | C5: 2583184228 | D5: 4 | E5: Hany Caballero | F5: Peeling despigmentate axila | G5: Deposito | H5: 2400
B6: 45827 | C6: 419056101 | D6: 6 | E6: Bianca Conte | F6: Peeling despigmentate codos | G6: Visa | H6: 3600
B7: 45853 | C7: 3386917913 | D7: 3 | E7: Lilian Cobox | F7: Peeling manos | G7: Visa | H7: 849.999
B8: 45917 | C8: 707020684 | D8: 3 | E8: Ada Briceño | F8: Peeling manos | G8: Visa | H8: 1050
B9: 45926 | C9: 1444564183 | D9: 3 | E9: Olga Garcia Pantaleón | F9: peeling manos | G9: Visa | H9: 1140
B10: 45939 | C10: 2570735132 | D10: 3 | E10: Karla Sapper | F10: Peeling despigmente glúteos | G10: Visa | H10: 1800
E11: Total | H11: =SUM(H3:H10) -> 13489.999

Sheet Spectra ginecologico
A1: Spectra ginecologico | B1: Fecha | C1: No. de Factura | D1: Cantidad | E1: Nombre del Paciente | F1: Tratamiento | G1: Forma de Pago | H1: Total
B3: 45674 | C3: 761415908 | D3: 2 | E3: Carla De Zelaya | F3: Spectra ginecologico | G3: Visa | H3: 5000
B4: 45680 | C4: 1896892491 | D4: 2 | E4: Adriana Marroquin | F4: Spectra ginecologico | G4: Credomatic | H4: 5000
B5: 45786 | C5: 76993638 | D5: 2 | E5: Zoila Valencia | F5: Spectra ginecologico | G5: Credomatic | H5: 5000
B6: 45817 | C6: 3841346753 | D6: 2 | E6: Maria Fernanda Chavez | F6: Spectra ginecologico | G6: Visa | H6: 5500
B7: 45876 | C7: 1851084296 | D7: 2 | E7: Marisol Coronado | F7: Spectra ginecologico | G7: Visa | H7: 5000
E8: Total | H8: =SUM(H3:H7) -> 25500

Sheet Eliminación de lunares
A1: Eliminación de lunares | B1: Fecha | C1: No. de Factura | D1: Cantidad | E1: Nombre del Paciente | F1: Tratamiento | G1: Forma de Pago | H1: Total
B3: --- | C3: --- | D3: --- | E3: --- | F3: --- | G3: --- | H3: 0
E4: Total | H4: =SUM(H3:H3) -> 0

Sheet Botox
A1: Botox | B1: Fecha | C1: No. de Factura | D1: Cantidad | E1: Nombre del Paciente | F1: Tratamiento | G1: Forma de Pago | H1: Total
B3: 45741 | C3: 191186041 | D3: 64 | E3: Ana Luisa Martinez | F3: Aplicación de botox | G3: Credomatic | H3: 3520
B4: 45741 | C4: 2828223427 | D4: 45 | E4: Caro Vasquez | F4: Aplicación de botox | G4: Credomatic | H4: 2475
B5: 45741 | C5: 2551202003 | D5: 25 | E5: Maria Jose Gonzalez | F5: Aplicación de botox | G5: Efectivo | H5: 1375
B6: 45741 | C6: 382681631 | D6: 19 | E6: Monica Cruz | F6: Aplicación de botox | G6: Credomatic | H6: 1045
B7: 45741 | C7: 501434772 | D7: 59 | E7: Ana Lorena Meyer | F7: Aplicación de botox | G7: Credomatic | H7: 3245
B8: 45741 | C8: 970606632 | D8: 38 | E8: Margarita Dominguez | F8: Aplicación de botox | G8: Credomatic | H8: 2090
B9: 45741 | C9: 305610913 | D9: 59 | E9: Victor Hugo Morales | F9: Aplicación de botox | G9: Credomatic | H9: 3245
